Workbook

Sheet README
A1: Merged Eurostat SBS C29 NUTS dataset
A2: Created | B2: Derived 2021–2023 employment and appended to 2008–2020 employment
A3: Employment formula | B3: employment_derived_year = persons employed per local unit × local units
A4: Source 2008–2020 | B4: sbs_r_nuts06_r2__custom_21203905_spreadsheet.xlsx
A5: Source 2021–2023 | B5: sbs_r_nuts2021__custom_21203869_spreadsheet.xlsx
A6: Sheets | B6: Post2020_Derivation, Employment_Merged, LocalUnits_Merged, Wages_Merged
A7: Note | B7: Missing values (:) and Eurostat flags are preserved.
A8: Old employment rows | B8: 547
A9: Post-2020 derivation rows | B9: 416
A10: Union GEO rows | B10: 578

Sheet Post2020_Derivation
A1: GEO code | B1: GEO label | C1: emp_per_local_unit_2021 | D1: flag_emp_per_local_unit_2021 | E1: local_units_2021 | F1: flag_local_units_2021 | G1: employment_derived_2021 | H1: derived_flag_2021 | I1: emp_per_local_unit_2022 | J1: flag_emp_per_local_unit_2022 | K1: local_units_2022 | L1: flag_local_units_2022 | M1: employment_derived_2022 | N1: derived_flag_2022 | O1: emp_per_local_unit_2023 | P1: flag_emp_per_local_unit_2023 | Q1: local_units_2023 | R1: flag_local_units_2023 | S1: employment_derived_2023 | T1: derived_flag_2023
A2: BE | B2: Belgium | C2: 87 | E2: 336 | G2: =IF(OR(C2="",C2=":",E2="",E2=":"),"",C2*E2) -> 29232 | H2: =IF(_xludf.TEXTJOIN("; ",TRUE,D2,F2)="","",_xludf.TEXTJOIN("; ",TRUE,D2,F2)) -> #NAME? | I2: 57 | K2: 543 | M2: =IF(OR(I2="",I2=":",K2="",K2=":"),"",I2*K2) -> 30951 | N2: =IF(_xludf.TEXTJOIN("; ",TRUE,J2,L2)="","",_xludf.TEXTJOIN("; ",TRUE,J2,L2)) -> #NAME? | O2: 61 | Q2: 487 | S2: =IF(OR(O2="",O2=":",Q2="",Q2=":"),"",O2*Q2) -> 29707 | T2: =IF(_xludf.TEXTJOIN("; ",TRUE,P2,R2)="","",_xludf.TEXTJOIN("; ",TRUE,P2,R2)) -> #NAME?
A3: BE1 | B3: Région de Bruxelles-Capitale/Brussels Hoofdstedelijk Gewest | C3: 210 | E3: 17 | G3: =IF(OR(C3="",C3=":",E3="",E3=":"),"",C3*E3) -> 3570 | H3: =IF(_xludf.TEXTJOIN("; ",TRUE,D3,F3)="","",_xludf.TEXTJOIN("; ",TRUE,D3,F3)) -> #NAME? | I3: 144 | K3: 28 | M3: =IF(OR(I3="",I3=":",K3="",K3=":"),"",I3*K3) -> 4032 | N3: =IF(_xludf.TEXTJOIN("; ",TRUE,J3,L3)="","",_xludf.TEXTJOIN("; ",TRUE,J3,L3)) -> #NAME? | O3: 144 | Q3: 25 | S3: =IF(OR(O3="",O3=":",Q3="",Q3=":"),"",O3*Q3) -> 3600 | T3: =IF(_xludf.TEXTJOIN("; ",TRUE,P3,R3)="","",_xludf.TEXTJOIN("; ",TRUE,P3,R3)) -> #NAME?
A4: BE10 | B4: Région de Bruxelles-Capitale/Brussels Hoofdstedelijk Gewest | C4: 210 | E4: 17 | G4: =IF(OR(C4="",C4=":",E4="",E4=":"),"",C4*E4) -> 3570 | H4: =IF(_xludf.TEXTJOIN("; ",TRUE,D4,F4)="","",_xludf.TEXTJOIN("; ",TRUE,D4,F4)) -> #NAME? | I4: 144 | K4: 28 | M4: =IF(OR(I4="",I4=":",K4="",K4=":"),"",I4*K4) -> 4032 | N4: =IF(_xludf.TEXTJOIN("; ",TRUE,J4,L4)="","",_xludf.TEXTJOIN("; ",TRUE,J4,L4)) -> #NAME? | O4: 144 | Q4: 25 | S4: =IF(OR(O4="",O4=":",Q4="",Q4=":"),"",O4*Q4) -> 3600 | T4: =IF(_xludf.TEXTJOIN("; ",TRUE,P4,R4)="","",_xludf.TEXTJOIN("; ",TRUE,P4,R4)) -> #NAME?
A5: BE2 | B5: Vlaams Gewest | C5: : | D5: C | E5: : | F5: C | G5: =IF(OR(C5="",C5=":",E5="",E5=":"),"",C5*E5) | H5: =IF(_xludf.TEXTJOIN("; ",TRUE,D5,F5)="","",_xludf.TEXTJOIN("; ",TRUE,D5,F5)) -> #NAME? | I5: 64 | K5: 395 | M5: =IF(OR(I5="",I5=":",K5="",K5=":"),"",I5*K5) -> 25280 | N5: =IF(_xludf.TEXTJOIN("; ",TRUE,J5,L5)="","",_xludf.TEXTJOIN("; ",TRUE,J5,L5)) -> #NAME? | O5: 70 | Q5: 350 | S5: =IF(OR(O5="",O5=":",Q5="",Q5=":"),"",O5*Q5) -> 24500 | T5: =IF(_xludf.TEXTJOIN("; ",TRUE,P5,R5)="","",_xludf.TEXTJOIN("; ",TRUE,P5,R5)) -> #NAME?
A6: BE21 | B6: Prov. Antwerpen | C6: 110 | E6: 56 | G6: =IF(OR(C6="",C6=":",E6="",E6=":"),"",C6*E6) -> 6160 | H6: =IF(_xludf.TEXTJOIN("; ",TRUE,D6,F6)="","",_xludf.TEXTJOIN("; ",TRUE,D6,F6)) -> #NAME? | I6: 64 | K6: 95 | M6: =IF(OR(I6="",I6=":",K6="",K6=":"),"",I6*K6) -> 6080 | N6: =IF(_xludf.TEXTJOIN("; ",TRUE,J6,L6)="","",_xludf.TEXTJOIN("; ",TRUE,J6,L6)) -> #NAME? | O6: 76 | Q6: 78 | S6: =IF(OR(O6="",O6=":",Q6="",Q6=":"),"",O6*Q6) -> 5928 | T6: =IF(_xludf.TEXTJOIN("; ",TRUE,P6,R6)="","",_xludf.TEXTJOIN("; ",TRUE,P6,R6)) -> #NAME?
A7: BE22 | B7: Prov. Limburg (BE) | C7: : | D7: C | E7: : | F7: C | G7: =IF(OR(C7="",C7=":",E7="",E7=":"),"",C7*E7) | H7: =IF(_xludf.TEXTJOIN("; ",TRUE,D7,F7)="","",_xludf.TEXTJOIN("; ",TRUE,D7,F7)) -> #NAME? | I7: 43 | K7: 70 | M7: =IF(OR(I7="",I7=":",K7="",K7=":"),"",I7*K7) -> 3010 | N7: =IF(_xludf.TEXTJOIN("; ",TRUE,J7,L7)="","",_xludf.TEXTJOIN("; ",TRUE,J7,L7)) -> #NAME? | O7: 47 | Q7: 66 | S7: =IF(OR(O7="",O7=":",Q7="",Q7=":"),"",O7*Q7) -> 3102 | T7: =IF(_xludf.TEXTJOIN("; ",TRUE,P7,R7)="","",_xludf.TEXTJOIN("; ",TRUE,P7,R7)) -> #NAME?
A8: BE23 | B8: Prov. Oost-Vlaanderen | C8: 206 | E8: 56 | G8: =IF(OR(C8="",C8=":",E8="",E8=":"),"",C8*E8) -> 11536 | H8: =IF(_xludf.TEXTJOIN("; ",TRUE,D8,F8)="","",_xludf.TEXTJOIN("; ",TRUE,D8,F8)) -> #NAME? | I8: 143 | K8: 88 | M8: =IF(OR(I8="",I8=":",K8="",K8=":"),"",I8*K8) -> 12584 | N8: =IF(_xludf.TEXTJOIN("; ",TRUE,J8,L8)="","",_xludf.TEXTJOIN("; ",TRUE,J8,L8)) -> #NAME? | O8: 160 | Q8: 78 | S8: =IF(OR(O8="",O8=":",Q8="",Q8=":"),"",O8*Q8) -> 12480 | T8: =IF(_xludf.TEXTJOIN("; ",TRUE,P8,R8)="","",_xludf.TEXTJOIN("; ",TRUE,P8,R8)) -> #NAME?
A9: BE24 | B9: Prov. Vlaams-Brabant | C9: 60 | E9: 21 | G9: =IF(OR(C9="",C9=":",E9="",E9=":"),"",C9*E9) -> 1260 | H9: =IF(_xludf.TEXTJOIN("; ",TRUE,D9,F9)="","",_xludf.TEXTJOIN("; ",TRUE,D9,F9)) -> #NAME? | I9: 31 | K9: 38 | M9: =IF(OR(I9="",I9=":",K9="",K9=":"),"",I9*K9) -> 1178 | N9: =IF(_xludf.TEXTJOIN("; ",TRUE,J9,L9)="","",_xludf.TEXTJOIN("; ",TRUE,J9,L9)) -> #NAME? | O9: 24 | Q9: 36 | S9: =IF(OR(O9="",O9=":",Q9="",Q9=":"),"",O9*Q9) -> 864 | T9: =IF(_xludf.TEXTJOIN("; ",TRUE,P9,R9)="","",_xludf.TEXTJOIN("; ",TRUE,P9,R9)) -> #NAME?
A10: BE25 | B10: Prov. West-Vlaanderen | C10: 37 | E10: 69 | G10: =IF(OR(C10="",C10=":",E10="",E10=":"),"",C10*E10) -> 2553 | H10: =IF(_xludf.TEXTJOIN("; ",TRUE,D10,F10)="","",_xludf.TEXTJOIN("; ",TRUE,D10,F10)) -> #NAME? | I10: 24 | K10: 104 | M10: =IF(OR(I10="",I10=":",K10="",K10=":"),"",I10*K10) -> 2496 | N10: =IF(_xludf.TEXTJOIN("; ",TRUE,J10,L10)="","",_xludf.TEXTJOIN("; ",TRUE,J10,L10)) -> #NAME? | O10: 24 | Q10: 92 | S10: =IF(OR(O10="",O10=":",Q10="",Q10=":"),"",O10*Q10) -> 2208 | T10: =IF(_xludf.TEXTJOIN("; ",TRUE,P10,R10)="","",_xludf.TEXTJOIN("; ",TRUE,P10,R10)) -> #NAME?
A11: BE3 | B11: Région wallonne | C11: : | D11: C | E11: : | F11: C | G11: =IF(OR(C11="",C11=":",E11="",E11=":"),"",C11*E11) | H11: =IF(_xludf.TEXTJOIN("; ",TRUE,D11,F11)="","",_xludf.TEXTJOIN("; ",TRUE,D11,F11)) -> #NAME? | I11: 12 | K11: 114 | M11: =IF(OR(I11="",I11=":",K11="",K11=":"),"",I11*K11) -> 1368 | N11: =IF(_xludf.TEXTJOIN("; ",TRUE,J11,L11)="","",_xludf.TEXTJOIN("; ",TRUE,J11,L11)) -> #NAME? | O11: 12 | Q11: 104 | S11: =IF(OR(O11="",O11=":",Q11="",Q11=":"),"",O11*Q11) -> 1248 | T11: =IF(_xludf.TEXTJOIN("; ",TRUE,P11,R11)="","",_xludf.TEXTJOIN("; ",TRUE,P11,R11)) -> #NAME?
A12: BE31 | B12: Prov. Brabant wallon | C12: 36 | E12: 3 | G12: =IF(OR(C12="",C12=":",E12="",E12=":"),"",C12*E12) -> 108 | H12: =IF(_xludf.TEXTJOIN("; ",TRUE,D12,F12)="","",_xludf.TEXTJOIN("; ",TRUE,D12,F12)) -> #NAME? | I12: 11 | K12: 12 | M12: =IF(OR(I12="",I12=":",K12="",K12=":"),"",I12*K12) -> 132 | N12: =IF(_xludf.TEXTJOIN("; ",TRUE,J12,L12)="","",_xludf.TEXTJOIN("; ",TRUE,J12,L12)) -> #NAME? | O12: 18 | Q12: 7 | S12: =IF(OR(O12="",O12=":",Q12="",Q12=":"),"",O12*Q12) -> 126 | T12: =IF(_xludf.TEXTJOIN("; ",TRUE,P12,R12)="","",_xludf.TEXTJOIN("; ",TRUE,P12,R12)) -> #NAME?
A13: BE32 | B13: Prov. Hainaut | C13: 14 | E13: 23 | G13: =IF(OR(C13="",C13=":",E13="",E13=":"),"",C13*E13) -> 322 | H13: =IF(_xludf.TEXTJOIN("; ",TRUE,D13,F13)="","",_xludf.TEXTJOIN("; ",TRUE,D13,F13)) -> #NAME? | I13: 10 | K13: 31 | M13: =IF(OR(I13="",I13=":",K13="",K13=":"),"",I13*K13) -> 310 | N13: =IF(_xludf.TEXTJOIN("; ",TRUE,J13,L13)="","",_xludf.TEXTJOIN("; ",TRUE,J13,L13)) -> #NAME? | O13: : | P13: C | Q13: : | R13: C | S13: =IF(OR(O13="",O13=":",Q13="",Q13=":"),"",O13*Q13) | T13: =IF(_xludf.TEXTJOIN("; ",TRUE,P13,R13)="","",_xludf.TEXTJOIN("; ",TRUE,P13,R13)) -> #NAME?
A14: BE33 | B14: Prov. Liège | C14: : | D14: C | E14: : | F14: C | G14: =IF(OR(C14="",C14=":",E14="",E14=":"),"",C14*E14) | H14: =IF(_xludf.TEXTJOIN("; ",TRUE,D14,F14)="","",_xludf.TEXTJOIN("; ",TRUE,D14,F14)) -> #NAME? | I14: 13 | K14: 50 | M14: =IF(OR(I14="",I14=":",K14="",K14=":"),"",I14*K14) -> 650 | N14: =IF(_xludf.TEXTJOIN("; ",TRUE,J14,L14)="","",_xludf.TEXTJOIN("; ",TRUE,J14,L14)) -> #NAME? | O14: 13 | Q14: 48 | S14: =IF(OR(O14="",O14=":",Q14="",Q14=":"),"",O14*Q14) -> 624 | T14: =IF(_xludf.TEXTJOIN("; ",TRUE,P14,R14)="","",_xludf.TEXTJOIN("; ",TRUE,P14,R14)) -> #NAME?
A15: BE34 | B15: Prov. Luxembourg (BE) | C15: 58 | E15: 4 | G15: =IF(OR(C15="",C15=":",E15="",E15=":"),"",C15*E15) -> 232 | H15: =IF(_xludf.TEXTJOIN("; ",TRUE,D15,F15)="","",_xludf.TEXTJOIN("; ",TRUE,D15,F15)) -> #NAME? | I15: 77 | K15: 3 | M15: =IF(OR(I15="",I15=":",K15="",K15=":"),"",I15*K15) -> 231 | N15: =IF(_xludf.TEXTJOIN("; ",TRUE,J15,L15)="","",_xludf.TEXTJOIN("; ",TRUE,J15,L15)) -> #NAME? | O15: : | P15: C | Q15: : | R15: C | S15: =IF(OR(O15="",O15=":",Q15="",Q15=":"),"",O15*Q15) | T15: =IF(_xludf.TEXTJOIN("; ",TRUE,P15,R15)="","",_xludf.TEXTJOIN("; ",TRUE,P15,R15)) -> #NAME?
A16: BE35 | B16: Prov. Namur | C16: 6 | E16: 10 | G16: =IF(OR(C16="",C16=":",E16="",E16=":"),"",C16*E16) -> 60 | H16: =IF(_xludf.TEXTJOIN("; ",TRUE,D16,F16)="","",_xludf.TEXTJOIN("; ",TRUE,D16,F16)) -> #NAME? | I16: 4 | K16: 18 | M16: =IF(OR(I16="",I16=":",K16="",K16=":"),"",I16*K16) -> 72 | N16: =IF(_xludf.TEXTJOIN("; ",TRUE,J16,L16)="","",_xludf.TEXTJOIN("; ",TRUE,J16,L16)) -> #NAME? | O16: : | P16: C | Q16: : | R16: C | S16: =IF(OR(O16="",O16=":",Q16="",Q16=":"),"",O16*Q16) | T16: =IF(_xludf.TEXTJOIN("; ",TRUE,P16,R16)="","",_xludf.TEXTJOIN("; ",TRUE,P16,R16)) -> #NAME?
A17: BEZ | B17: Extra-Regio NUTS 1 | C17: : | D17: C | E17: : | F17: C | G17: =IF(OR(C17="",C17=":",E17="",E17=":"),"",C17*E17) | H17: =IF(_xludf.TEXTJOIN("; ",TRUE,D17,F17)="","",_xludf.TEXTJOIN("; ",TRUE,D17,F17)) -> #NAME? | I17: 3 | K17: 6 | M17: =IF(OR(I17="",I17=":",K17="",K17=":"),"",I17*K17) -> 18 | N17: =IF(_xludf.TEXTJOIN("; ",TRUE,J17,L17)="","",_xludf.TEXTJOIN("; ",TRUE,J17,L17)) -> #NAME? | O17: 4 | Q17: 8 | S17: =IF(OR(O17="",O17=":",Q17="",Q17=":"),"",O17*Q17) -> 32 | T17: =IF(_xludf.TEXTJOIN("; ",TRUE,P17,R17)="","",_xludf.TEXTJOIN("; ",TRUE,P17,R17)) -> #NAME?
A18: BEZZ | B18: Extra-Regio NUTS 2 | C18: : | D18: C | E18: : | F18: C | G18: =IF(OR(C18="",C18=":",E18="",E18=":"),"",C18*E18) | H18: =IF(_xludf.TEXTJOIN("; ",TRUE,D18,F18)="","",_xludf.TEXTJOIN("; ",TRUE,D18,F18)) -> #NAME? | I18: 3 | K18: 6 | M18: =IF(OR(I18="",I18=":",K18="",K18=":"),"",I18*K18) -> 18 | N18: =IF(_xludf.TEXTJOIN("; ",TRUE,J18,L18)="","",_xludf.TEXTJOIN("; ",TRUE,J18,L18)) -> #NAME? | O18: 4 | Q18: 8 | S18: =IF(OR(O18="",O18=":",Q18="",Q18=":"),"",O18*Q18) -> 32 | T18: =IF(_xludf.TEXTJOIN("; ",TRUE,P18,R18)="","",_xludf.TEXTJOIN("; ",TRUE,P18,R18)) -> #NAME?
A19: BG | B19: Bulgaria | C19: 169 | E19: 156 | G19: =IF(OR(C19="",C19=":",E19="",E19=":"),"",C19*E19) -> 26364 | H19: =IF(_xludf.TEXTJOIN("; ",TRUE,D19,F19)="","",_xludf.TEXTJOIN("; ",TRUE,D19,F19)) -> #NAME? | I19: 163 | K19: 155 | M19: =IF(OR(I19="",I19=":",K19="",K19=":"),"",I19*K19) -> 25265 | N19: =IF(_xludf.TEXTJOIN("; ",TRUE,J19,L19)="","",_xludf.TEXTJOIN("; ",TRUE,J19,L19)) -> #NAME? | O19: 160 | Q19: 159 | S19: =IF(OR(O19="",O19=":",Q19="",Q19=":"),"",O19*Q19) -> 25440 | T19: =IF(_xludf.TEXTJOIN("; ",TRUE,P19,R19)="","",_xludf.TEXTJOIN("; ",TRUE,P19,R19)) -> #NAME?
A20: BG3 | B20: Severna i Yugoiztochna Bulgaria | C20: 158 | E20: 79 | G20: =IF(OR(C20="",C20=":",E20="",E20=":"),"",C20*E20) -> 12482 | H20: =IF(_xludf.TEXTJOIN("; ",TRUE,D20,F20)="","",_xludf.TEXTJOIN("; ",TRUE,D20,F20)) -> #NAME? | I20: 149 | K20: 85 | M20: =IF(OR(I20="",I20=":",K20="",K20=":"),"",I20*K20) -> 12665 | N20: =IF(_xludf.TEXTJOIN("; ",TRUE,J20,L20)="","",_xludf.TEXTJOIN("; ",TRUE,J20,L20)) -> #NAME? | O20: 156 | Q20: 82 | S20: =IF(OR(O20="",O20=":",Q20="",Q20=":"),"",O20*Q20) -> 12792 | T20: =IF(_xludf.TEXTJOIN("; ",TRUE,P20,R20)="","",_xludf.TEXTJOIN("; ",TRUE,P20,R20)) -> #NAME?
A21: BG31 | B21: Severozapaden | C21: 219 | E21: 17 | G21: =IF(OR(C21="",C21=":",E21="",E21=":"),"",C21*E21) -> 3723 | H21: =IF(_xludf.TEXTJOIN("; ",TRUE,D21,F21)="","",_xludf.TEXTJOIN("; ",TRUE,D21,F21)) -> #NAME? | I21: 244 | K21: 17 | M21: =IF(OR(I21="",I21=":",K21="",K21=":"),"",I21*K21) -> 4148 | N21: =IF(_xludf.TEXTJOIN("; ",TRUE,J21,L21)="","",_xludf.TEXTJOIN("; ",TRUE,J21,L21)) -> #NAME? | O21: 277 | Q21: 16 | S21: =IF(OR(O21="",O21=":",Q21="",Q21=":"),"",O21*Q21) -> 4432 | T21: =IF(_xludf.TEXTJOIN("; ",TRUE,P21,R21)="","",_xludf.TEXTJOIN("; ",TRUE,P21,R21)) -> #NAME?
A22: BG32 | B22: Severen tsentralen | C22: 107 | E22: 22 | G22: =IF(OR(C22="",C22=":",E22="",E22=":"),"",C22*E22) -> 2354 | H22: =IF(_xludf.TEXTJOIN("; ",TRUE,D22,F22)="","",_xludf.TEXTJOIN("; ",TRUE,D22,F22)) -> #NAME? | I22: 101 | K22: 24 | M22: =IF(OR(I22="",I22=":",K22="",K22=":"),"",I22*K22) -> 2424 | N22: =IF(_xludf.TEXTJOIN("; ",TRUE,J22,L22)="","",_xludf.TEXTJOIN("; ",TRUE,J22,L22)) -> #NAME? | O22: 116 | Q22: 24 | S22: =IF(OR(O22="",O22=":",Q22="",Q22=":"),"",O22*Q22) -> 2784 | T22: =IF(_xludf.TEXTJOIN("; ",TRUE,P22,R22)="","",_xludf.TEXTJOIN("; ",TRUE,P22,R22)) -> #NAME?
A23: BG33 | B23: Severoiztochen | C23: 4 | E23: 14 | G23: =IF(OR(C23="",C23=":",E23="",E23=":"),"",C23*E23) -> 56 | H23: =IF(_xludf.TEXTJOIN("; ",TRUE,D23,F23)="","",_xludf.TEXTJOIN("; ",TRUE,D23,F23)) -> #NAME? | I23: 7 | K23: 14 | M23: =IF(OR(I23="",I23=":",K23="",K23=":"),"",I23*K23) -> 98 | N23: =IF(_xludf.TEXTJOIN("; ",TRUE,J23,L23)="","",_xludf.TEXTJOIN("; ",TRUE,J23,L23)) -> #NAME? | O23: 5 | Q23: 13 | S23: =IF(OR(O23="",O23=":",Q23="",Q23=":"),"",O23*Q23) -> 65 | T23: =IF(_xludf.TEXTJOIN("; ",TRUE,P23,R23)="","",_xludf.TEXTJOIN("; ",TRUE,P23,R23)) -> #NAME?
A24: BG34 | B24: Yugoiztochen | C24: 244 | E24: 26 | G24: =IF(OR(C24="",C24=":",E24="",E24=":"),"",C24*E24) -> 6344 | H24: =IF(_xludf.TEXTJOIN("; ",TRUE,D24,F24)="","",_xludf.TEXTJOIN("; ",TRUE,D24,F24)) -> #NAME? | I24: 199 | K24: 30 | M24: =IF(OR(I24="",I24=":",K24="",K24=":"),"",I24*K24) -> 5970 | N24: =IF(_xludf.TEXTJOIN("; ",TRUE,J24,L24)="","",_xludf.TEXTJOIN("; ",TRUE,J24,L24)) -> #NAME? | O24: 191 | Q24: 29 | S24: =IF(OR(O24="",O24=":",Q24="",Q24=":"),"",O24*Q24) -> 5539 | T24: =IF(_xludf.TEXTJOIN("; ",TRUE,P24,R24)="","",_xludf.TEXTJOIN("; ",TRUE,P24,R24)) -> #NAME?
A25: BG4 | B25: Yugozapadna i Yuzhna tsentralna Bulgaria | C25: 181 | E25: 77 | G25: =IF(OR(C25="",C25=":",E25="",E25=":"),"",C25*E25) -> 13937 | H25: =IF(_xludf.TEXTJOIN("; ",TRUE,D25,F25)="","",_xludf.TEXTJOIN("; ",TRUE,D25,F25)) -> #NAME? | I25: 181 | K25: 70 | M25: =IF(OR(I25="",I25=":",K25="",K25=":"),"",I25*K25) -> 12670 | N25: =IF(_xludf.TEXTJOIN("; ",TRUE,J25,L25)="","",_xludf.TEXTJOIN("; ",TRUE,J25,L25)) -> #NAME? | O25: 165 | Q25: 77 | S25: =IF(OR(O25="",O25=":",Q25="",Q25=":"),"",O25*Q25) -> 12705 | T25: =IF(_xludf.TEXTJOIN("; ",TRUE,P25,R25)="","",_xludf.TEXTJOIN("; ",TRUE,P25,R25)) -> #NAME?
A26: BG41 | B26: Yugozapaden | C26: 176 | E26: 36 | G26: =IF(OR(C26="",C26=":",E26="",E26=":"),"",C26*E26) -> 6336 | H26: =IF(_xludf.TEXTJOIN("; ",TRUE,D26,F26)="","",_xludf.TEXTJOIN("; ",TRUE,D26,F26)) -> #NAME? | I26: 187 | K26: 33 | M26: =IF(OR(I26="",I26=":",K26="",K26=":"),"",I26*K26) -> 6171 | N26: =IF(_xludf.TEXTJOIN("; ",TRUE,J26,L26)="","",_xludf.TEXTJOIN("; ",TRUE,J26,L26)) -> #NAME? | O26: 176 | Q26: 35 | S26: =IF(OR(O26="",O26=":",Q26="",Q26=":"),"",O26*Q26) -> 6160 | T26: =IF(_xludf.TEXTJOIN("; ",TRUE,P26,R26)="","",_xludf.TEXTJOIN("; ",TRUE,P26,R26)) -> #NAME?
A27: BG42 | B27: Yuzhen tsentralen | C27: 185 | E27: 41 | G27: =IF(OR(C27="",C27=":",E27="",E27=":"),"",C27*E27) -> 7585 | H27: =IF(_xludf.TEXTJOIN("; ",TRUE,D27,F27)="","",_xludf.TEXTJOIN("; ",TRUE,D27,F27)) -> #NAME? | I27: 175 | K27: 37 | M27: =IF(OR(I27="",I27=":",K27="",K27=":"),"",I27*K27) -> 6475 | N27: =IF(_xludf.TEXTJOIN("; ",TRUE,J27,L27)="","",_xludf.TEXTJOIN("; ",TRUE,J27,L27)) -> #NAME? | O27: 155 | Q27: 42 | S27: =IF(OR(O27="",O27=":",Q27="",Q27=":"),"",O27*Q27) -> 6510 | T27: =IF(_xludf.TEXTJOIN("; ",TRUE,P27,R27)="","",_xludf.TEXTJOIN("; ",TRUE,P27,R27)) -> #NAME?
A28: CZ | B28: Czechia | C28: 126 | E28: 1384 | G28: =IF(OR(C28="",C28=":",E28="",E28=":"),"",C28*E28) -> 174384 | H28: =IF(_xludf.TEXTJOIN("; ",TRUE,D28,F28)="","",_xludf.TEXTJOIN("; ",TRUE,D28,F28)) -> #NAME? | I28: 125 | K28: 1376 | M28: =IF(OR(I28="",I28=":",K28="",K28=":"),"",I28*K28) -> 172000 | N28: =IF(_xludf.TEXTJOIN("; ",TRUE,J28,L28)="","",_xludf.TEXTJOIN("; ",TRUE,J28,L28)) -> #NAME? | O28: 127 | Q28: 1360 | S28: =IF(OR(O28="",O28=":",Q28="",Q28=":"),"",O28*Q28) -> 172720 | T28: =IF(_xludf.TEXTJOIN("; ",TRUE,P28,R28)="","",_xludf.TEXTJOIN("; ",TRUE,P28,R28)) -> #NAME?
A29: CZ0 | B29: Česko | C29: 126 | E29: 1384 | G29: =IF(OR(C29="",C29=":",E29="",E29=":"),"",C29*E29) -> 174384 | H29: =IF(_xludf.TEXTJOIN("; ",TRUE,D29,F29)="","",_xludf.TEXTJOIN("; ",TRUE,D29,F29)) -> #NAME? | I29: 125 | K29: 1376 | M29: =IF(OR(I29="",I29=":",K29="",K29=":"),"",I29*K29) -> 172000 | N29: =IF(_xludf.TEXTJOIN("; ",TRUE,J29,L29)="","",_xludf.TEXTJOIN("; ",TRUE,J29,L29)) -> #NAME? | O29: 127 | Q29: 1360 | S29: =IF(OR(O29="",O29=":",Q29="",Q29=":"),"",O29*Q29) -> 172720 | T29: =IF(_xludf.TEXTJOIN("; ",TRUE,P29,R29)="","",_xludf.TEXTJOIN("; ",TRUE,P29,R29)) -> #NAME?
A30: CZ01 | B30: Praha | C30: 12 | E30: 159 | G30: =IF(OR(C30="",C30=":",E30="",E30=":"),"",C30*E30) -> 1908 | H30: =IF(_xludf.TEXTJOIN("; ",TRUE,D30,F30)="","",_xludf.TEXTJOIN("; ",TRUE,D30,F30)) -> #NAME? | I30: 19 | K30: 188 | M30: =IF(OR(I30="",I30=":",K30="",K30=":"),"",I30*K30) -> 3572 | N30: =IF(_xludf.TEXTJOIN("; ",TRUE,J30,L30)="","",_xludf.TEXTJOIN("; ",TRUE,J30,L30)) -> #NAME? | O30: 16 | Q30: 188 | S30: =IF(OR(O30="",O30=":",Q30="",Q30=":"),"",O30*Q30) -> 3008 | T30: =IF(_xludf.TEXTJOIN("; ",TRUE,P30,R30)="","",_xludf.TEXTJOIN("; ",TRUE,P30,R30)) -> #NAME?
... A37: CZ08 | B37: Moravskoslezsko | C37: 196 | E37: 119 | G37: =IF(OR(C37="",C37=":",E37="",E37=":"),"",C37*E37) -> 23324 | H37: =IF(_xludf.TEXTJOIN("; ",TRUE,D37,F37)="","",_xludf.TEXTJOIN("; ",TRUE,D37,F37)) -> #NAME? | I37: 186 | K37: 126 | M37: =IF(OR(I37="",I37=":",K37="",K37=":"),"",I37*K37) -> 23436 | N37: =IF(_xludf.TEXTJOIN("; ",TRUE,J37,L37)="","",_xludf.TEXTJOIN("; ",TRUE,J37,L37)) -> #NAME? | O37: 194 | Q37: 125 | S37: =IF(OR(O37="",O37=":",Q37="",Q37=":"),"",O37*Q37) -> 24250 | T37: =IF(_xludf.TEXTJOIN("; ",TRUE,P37,R37)="","",_xludf.TEXTJOIN("; ",TRUE,P37,R37)) -> #NAME?
A38: CZZ | B38: Extra-Regio NUTS 1 | C38: : | E38: 0 | G38: =IF(OR(C38="",C38=":",E38="",E38=":"),"",C38*E38) | H38: =IF(_xludf.TEXTJOIN("; ",TRUE,D38,F38)="","",_xludf.TEXTJOIN("; ",TRUE,D38,F38)) -> #NAME? | I38: : | K38: 0 | M38: =IF(OR(I38="",I38=":",K38="",K38=":"),"",I38*K38) | N38: =IF(_xludf.TEXTJOIN("; ",TRUE,J38,L38)="","",_xludf.TEXTJOIN("; ",TRUE,J38,L38)) -> #NAME? | O38: : | Q38: 0 | S38: =IF(OR(O38="",O38=":",Q38="",Q38=":"),"",O38*Q38) | T38: =IF(_xludf.TEXTJOIN("; ",TRUE,P38,R38)="","",_xludf.TEXTJOIN("; ",TRUE,P38,R38)) -> #NAME?
A39: CZZZ | B39: Extra-Regio NUTS 2 | C39: : | E39: 0 | G39: =IF(OR(C39="",C39=":",E39="",E39=":"),"",C39*E39) | H39: =IF(_xludf.TEXTJOIN("; ",TRUE,D39,F39)="","",_xludf.TEXTJOIN("; ",TRUE,D39,F39)) -> #NAME? | I39: : | K39: 0 | M39: =IF(OR(I39="",I39=":",K39="",K39=":"),"",I39*K39) | N39: =IF(_xludf.TEXTJOIN("; ",TRUE,J39,L39)="","",_xludf.TEXTJOIN("; ",TRUE,J39,L39)) -> #NAME? | O39: : | Q39: 0 | S39: =IF(OR(O39="",O39=":",Q39="",Q39=":"),"",O39*Q39) | T39: =IF(_xludf.TEXTJOIN("; ",TRUE,P39,R39)="","",_xludf.TEXTJOIN("; ",TRUE,P39,R39)) -> #NAME?
A40: DK | B40: Denmark | C40: 23 | E40: 163 | G40: =IF(OR(C40="",C40=":",E40="",E40=":"),"",C40*E40) -> 3749 | H40: =IF(_xludf.TEXTJOIN("; ",TRUE,D40,F40)="","",_xludf.TEXTJOIN("; ",TRUE,D40,F40)) -> #NAME? | I40: 24 | K40: 162 | M40: =IF(OR(I40="",I40=":",K40="",K40=":"),"",I40*K40) -> 3888 | N40: =IF(_xludf.TEXTJOIN("; ",TRUE,J40,L40)="","",_xludf.TEXTJOIN("; ",TRUE,J40,L40)) -> #NAME? | O40: 25 | Q40: 158 | S40: =IF(OR(O40="",O40=":",Q40="",Q40=":"),"",O40*Q40) -> 3950 | T40: =IF(_xludf.TEXTJOIN("; ",TRUE,P40,R40)="","",_xludf.TEXTJOIN("; ",TRUE,P40,R40)) -> #NAME?
A41: DK0 | B41: Danmark | C41: 23 | E41: 163 | G41: =IF(OR(C41="",C41=":",E41="",E41=":"),"",C41*E41) -> 3749 | H41: =IF(_xludf.TEXTJOIN("; ",TRUE,D41,F41)="","",_xludf.TEXTJOIN("; ",TRUE,D41,F41)) -> #NAME? | I41: 24 | K41: 162 | M41: =IF(OR(I41="",I41=":",K41="",K41=":"),"",I41*K41) -> 3888 | N41: =IF(_xludf.TEXTJOIN("; ",TRUE,J41,L41)="","",_xludf.TEXTJOIN("; ",TRUE,J41,L41)) -> #NAME? | O41: 25 | Q41: 158 | S41: =IF(OR(O41="",O41=":",Q41="",Q41=":"),"",O41*Q41) -> 3950 | T41: =IF(_xludf.TEXTJOIN("; ",TRUE,P41,R41)="","",_xludf.TEXTJOIN("; ",TRUE,P41,R41)) -> #NAME?
A42: DK01 | B42: Hovedstaden | C42: 12 | E42: 24 | G42: =IF(OR(C42="",C42=":",E42="",E42=":"),"",C42*E42) -> 288 | H42: =IF(_xludf.TEXTJOIN("; ",TRUE,D42,F42)="","",_xludf.TEXTJOIN("; ",TRUE,D42,F42)) -> #NAME? | I42: 11 | K42: 22 | M42: =IF(OR(I42="",I42=":",K42="",K42=":"),"",I42*K42) -> 242 | N42: =IF(_xludf.TEXTJOIN("; ",TRUE,J42,L42)="","",_xludf.TEXTJOIN("; ",TRUE,J42,L42)) -> #NAME? | O42: 11 | Q42: 20 | S42: =IF(OR(O42="",O42=":",Q42="",Q42=":"),"",O42*Q42) -> 220 | T42: =IF(_xludf.TEXTJOIN("; ",TRUE,P42,R42)="","",_xludf.TEXTJOIN("; ",TRUE,P42,R42)) -> #NAME?
A43: DK02 | B43: Sjælland | C43: 23 | E43: 17 | G43: =IF(OR(C43="",C43=":",E43="",E43=":"),"",C43*E43) -> 391 | H43: =IF(_xludf.TEXTJOIN("; ",TRUE,D43,F43)="","",_xludf.TEXTJOIN("; ",TRUE,D43,F43)) -> #NAME? | I43: 26 | K43: 17 | M43: =IF(OR(I43="",I43=":",K43="",K43=":"),"",I43*K43) -> 442 | N43: =IF(_xludf.TEXTJOIN("; ",TRUE,J43,L43)="","",_xludf.TEXTJOIN("; ",TRUE,J43,L43)) -> #NAME? | O43: 29 | Q43: 17 | S43: =IF(OR(O43="",O43=":",Q43="",Q43=":"),"",O43*Q43) -> 493 | T43: =IF(_xludf.TEXTJOIN("; ",TRUE,P43,R43)="","",_xludf.TEXTJOIN("; ",TRUE,P43,R43)) -> #NAME?
A44: DK03 | B44: Syddanmark | C44: 25 | E44: 59 | G44: =IF(OR(C44="",C44=":",E44="",E44=":"),"",C44*E44) -> 1475 | H44: =IF(_xludf.TEXTJOIN("; ",TRUE,D44,F44)="","",_xludf.TEXTJOIN("; ",TRUE,D44,F44)) -> #NAME? | I44: 25 | K44: 58 | M44: =IF(OR(I44="",I44=":",K44="",K44=":"),"",I44*K44) -> 1450 | N44: =IF(_xludf.TEXTJOIN("; ",TRUE,J44,L44)="","",_xludf.TEXTJOIN("; ",TRUE,J44,L44)) -> #NAME? | O44: 24 | Q44: 60 | S44: =IF(OR(O44="",O44=":",Q44="",Q44=":"),"",O44*Q44) -> 1440 | T44: =IF(_xludf.TEXTJOIN("; ",TRUE,P44,R44)="","",_xludf.TEXTJOIN("; ",TRUE,P44,R44)) -> #NAME?
A45: DK04 | B45: Midtjylland | C45: 22 | E45: 50 | G45: =IF(OR(C45="",C45=":",E45="",E45=":"),"",C45*E45) -> 1100 | H45: =IF(_xludf.TEXTJOIN("; ",TRUE,D45,F45)="","",_xludf.TEXTJOIN("; ",TRUE,D45,F45)) -> #NAME? | I45: 23 | K45: 50 | M45: =IF(OR(I45="",I45=":",K45="",K45=":"),"",I45*K45) -> 1150 | N45: =IF(_xludf.TEXTJOIN("; ",TRUE,J45,L45)="","",_xludf.TEXTJOIN("; ",TRUE,J45,L45)) -> #NAME? | O45: 29 | Q45: 48 | S45: =IF(OR(O45="",O45=":",Q45="",Q45=":"),"",O45*Q45) -> 1392 | T45: =IF(_xludf.TEXTJOIN("; ",TRUE,P45,R45)="","",_xludf.TEXTJOIN("; ",TRUE,P45,R45)) -> #NAME?
A46: DK05 | B46: Nordjylland | C46: 38 | E46: 13 | G46: =IF(OR(C46="",C46=":",E46="",E46=":"),"",C46*E46) -> 494 | H46: =IF(_xludf.TEXTJOIN("; ",TRUE,D46,F46)="","",_xludf.TEXTJOIN("; ",TRUE,D46,F46)) -> #NAME? | I46: 34 | K46: 15 | M46: =IF(OR(I46="",I46=":",K46="",K46=":"),"",I46*K46) -> 510 | N46: =IF(_xludf.TEXTJOIN("; ",TRUE,J46,L46)="","",_xludf.TEXTJOIN("; ",TRUE,J46,L46)) -> #NAME? | O46: 36 | Q46: 13 | S46: =IF(OR(O46="",O46=":",Q46="",Q46=":"),"",O46*Q46) -> 468 | T46: =IF(_xludf.TEXTJOIN("; ",TRUE,P46,R46)="","",_xludf.TEXTJOIN("; ",TRUE,P46,R46)) -> #NAME?
...

Sheet Employment_Merged
A1: GEO code | B1: GEO label | C1: 2008 | D1: flag_2008 | E1: 2009 | F1: flag_2009 | G1: 2010 | H1: flag_2010 | I1: 2011 | J1: flag_2011 | K1: 2012 | L1: flag_2012 | M1: 2013 | N1: flag_2013 | O1: 2014 | P1: flag_2014 | Q1: 2015 | R1: flag_2015 | S1: 2016 | T1: flag_2016 | U1: 2017 | V1: flag_2017 | W1: 2018 | X1: flag_2018 | Y1: 2019 | Z1: flag_2019 | AA1: 2020 | AB1: flag_2020 | AC1: 2021 | AD1: flag_2021 | AE1: 2022 | AF1: flag_2022 | AG1: 2023 | AH1: flag_2023
A2: BE | B2: Belgium | C2: 42525 | E2: 38750 | G2: 34965 | I2: 36814 | K2: 38445 | M2: 36982 | O2: 35162 | Q2: 29556 | S2: 28187 | U2: 29211 | W2: 30287 | X2: b | Y2: 30720 | AA2: 30550 | AC2: =Post2020_Derivation!G2 -> 29232 | AD2: =IF(Post2020_Derivation!H2="","",Post2020_Derivation!H2) -> #NAME? | AE2: =Post2020_Derivation!M2 -> 30951 | AF2: =IF(Post2020_Derivation!N2="","",Post2020_Derivation!N2) -> #NAME? | AG2: =Post2020_Derivation!S2 -> 29707 | AH2: =IF(Post2020_Derivation!T2="","",Post2020_Derivation!T2) -> #NAME?
A3: BE1 | B3: Région de Bruxelles-Capitale/Brussels Hoofdstedelijk Gewest | C3: : | D3: C | E3: 4351 | G3: 3734 | I3: 4048 | K3: 4409 | M3: 4174 | O3: 3872 | Q3: 3975 | S3: 3993 | U3: 4227 | W3: 3029 | X3: b | Y3: 3318 | AA3: 3602 | AC3: =Post2020_Derivation!G3 -> 3570 | AD3: =IF(Post2020_Derivation!H3="","",Post2020_Derivation!H3) -> #NAME? | AE3: =Post2020_Derivation!M3 -> 4032 | AF3: =IF(Post2020_Derivation!N3="","",Post2020_Derivation!N3) -> #NAME? | AG3: =Post2020_Derivation!S3 -> 3600 | AH3: =IF(Post2020_Derivation!T3="","",Post2020_Derivation!T3) -> #NAME?
A4: BE10 | B4: Région de Bruxelles-Capitale/Brussels Hoofdstedelijk Gewest | C4: : | D4: C | E4: 4351 | G4: 3734 | I4: 4048 | K4: 4409 | M4: 4174 | O4: 3872 | Q4: 3975 | S4: 3993 | U4: 4227 | W4: 3029 | X4: b | Y4: 3318 | AA4: 3602 | AC4: =Post2020_Derivation!G4 -> 3570 | AD4: =IF(Post2020_Derivation!H4="","",Post2020_Derivation!H4) -> #NAME? | AE4: =Post2020_Derivation!M4 -> 4032 | AF4: =IF(Post2020_Derivation!N4="","",Post2020_Derivation!N4) -> #NAME? | AG4: =Post2020_Derivation!S4 -> 3600 | AH4: =IF(Post2020_Derivation!T4="","",Post2020_Derivation!T4) -> #NAME?
A5: BE2 | B5: Vlaams Gewest | C5: : | D5: C | E5: 31353 | G5: 28488 | I5: 30028 | K5: 31594 | M5: 30256 | O5: 28881 | Q5: 23810 | S5: 22279 | U5: 22882 | W5: 25248 | X5: b | Y5: 25493 | AA5: 25439 | AC5: =Post2020_Derivation!G5 | AD5: =IF(Post2020_Derivation!H5="","",Post2020_Derivation!H5) -> #NAME? | AE5: =Post2020_Derivation!M5 -> 25280 | AF5: =IF(Post2020_Derivation!N5="","",Post2020_Derivation!N5) -> #NAME? | AG5: =Post2020_Derivation!S5 -> 24500 | AH5: =IF(Post2020_Derivation!T5="","",Post2020_Derivation!T5) -> #NAME?
A6: BE21 | B6: Prov. Antwerpen | C6: 11865 | E6: : | F6: C | G6: 8162 | I6: 8661 | K6: 9043 | M6: 8723 | O6: 8105 | Q6: 7377 | S6: 6414 | U6: 6422 | W6: 6668 | X6: b | Y6: 6920 | AA6: 6470 | AC6: =Post2020_Derivation!G6 -> 6160 | AD6: =IF(Post2020_Derivation!H6="","",Post2020_Derivation!H6) -> #NAME? | AE6: =Post2020_Derivation!M6 -> 6080 | AF6: =IF(Post2020_Derivation!N6="","",Post2020_Derivation!N6) -> #NAME? | AG6: =Post2020_Derivation!S6 -> 5928 | AH6: =IF(Post2020_Derivation!T6="","",Post2020_Derivation!T6) -> #NAME?
A7: BE22 | B7: Prov. Limburg (BE) | C7: : | D7: C | E7: : | F7: C | G7: : | H7: C | I7: 7927 | K7: 8951 | M7: 8304 | O7: 7891 | Q7: 3442 | S7: 3319 | U7: 3781 | W7: 3879 | X7: b | Y7: 3741 | AA7: 3598 | AC7: =Post2020_Derivation!G7 | AD7: =IF(Post2020_Derivation!H7="","",Post2020_Derivation!H7) -> #NAME? | AE7: =Post2020_Derivation!M7 -> 3010 | AF7: =IF(Post2020_Derivation!N7="","",Post2020_Derivation!N7) -> #NAME? | AG7: =Post2020_Derivation!S7 -> 3102 | AH7: =IF(Post2020_Derivation!T7="","",Post2020_Derivation!T7) -> #NAME?
A8: BE23 | B8: Prov. Oost-Vlaanderen | C8: : | D8: C | E8: 7394 | G8: 8713 | I8: 9102 | K8: 9908 | M8: 9656 | O8: 9619 | Q8: 9907 | S8: 9726 | U8: 9846 | W8: 11061 | X8: b | Y8: 11352 | AA8: 11568 | AC8: =Post2020_Derivation!G8 -> 11536 | AD8: =IF(Post2020_Derivation!H8="","",Post2020_Derivation!H8) -> #NAME? | AE8: =Post2020_Derivation!M8 -> 12584 | AF8: =IF(Post2020_Derivation!N8="","",Post2020_Derivation!N8) -> #NAME? | AG8: =Post2020_Derivation!S8 -> 12480 | AH8: =IF(Post2020_Derivation!T8="","",Post2020_Derivation!T8) -> #NAME?
A9: BE24 | B9: Prov. Vlaams-Brabant | C9: : | D9: C | E9: 2172 | G9: : | H9: C | I9: 1887 | K9: 1837 | M9: 1811 | O9: 1688 | Q9: 1435 | S9: 1355 | U9: 1252 | W9: 1259 | X9: b | Y9: 1116 | AA9: 1386 | AC9: =Post2020_Derivation!G9 -> 1260 | AD9: =IF(Post2020_Derivation!H9="","",Post2020_Derivation!H9) -> #NAME? | AE9: =Post2020_Derivation!M9 -> 1178 | AF9: =IF(Post2020_Derivation!N9="","",Post2020_Derivation!N9) -> #NAME? | AG9: =Post2020_Derivation!S9 -> 864 | AH9: =IF(Post2020_Derivation!T9="","",Post2020_Derivation!T9) -> #NAME?
A10: BE25 | B10: Prov. West-Vlaanderen | C10: 2447 | E10: 2218 | G10: 1997 | I10: 2451 | K10: 1855 | M10: 1762 | O10: 1578 | Q10: 1649 | S10: 1465 | U10: 1581 | W10: 2381 | X10: b | Y10: 2364 | AA10: 2417 | AC10: =Post2020_Derivation!G10 -> 2553 | AD10: =IF(Post2020_Derivation!H10="","",Post2020_Derivation!H10) -> #NAME? | AE10: =Post2020_Derivation!M10 -> 2496 | AF10: =IF(Post2020_Derivation!N10="","",Post2020_Derivation!N10) -> #NAME? | AG10: =Post2020_Derivation!S10 -> 2208 | AH10: =IF(Post2020_Derivation!T10="","",Post2020_Derivation!T10) -> #NAME?
A11: BE3 | B11: Région wallonne | C11: : | D11: C | E11: 3031 | G11: 2726 | I11: 2731 | K11: 2438 | M11: 2534 | O11: 2341 | Q11: 1745 | S11: 1897 | U11: 2051 | W11: 1918 | X11: b | Y11: 1870 | AA11: 1492 | AC11: =Post2020_Derivation!G11 | AD11: =IF(Post2020_Derivation!H11="","",Post2020_Derivation!H11) -> #NAME? | AE11: =Post2020_Derivation!M11 -> 1368 | AF11: =IF(Post2020_Derivation!N11="","",Post2020_Derivation!N11) -> #NAME? | AG11: =Post2020_Derivation!S11 -> 1248 | AH11: =IF(Post2020_Derivation!T11="","",Post2020_Derivation!T11) -> #NAME?
A12: BE31 | B12: Prov. Brabant wallon | C12: : | D12: C | E12: 15 | G12: : | H12: C | I12: 101 | K12: 124 | M12: 135 | O12: 107 | Q12: 101 | S12: 97 | U12: 127 | W12: : | X12: bC | Y12: : | Z12: C | AA12: 154 | AC12: =Post2020_Derivation!G12 -> 108 | AD12: =IF(Post2020_Derivation!H12="","",Post2020_Derivation!H12) -> #NAME? | AE12: =Post2020_Derivation!M12 -> 132 | AF12: =IF(Post2020_Derivation!N12="","",Post2020_Derivation!N12) -> #NAME? | AG12: =Post2020_Derivation!S12 -> 126 | AH12: =IF(Post2020_Derivation!T12="","",Post2020_Derivation!T12) -> #NAME?
A13: BE32 | B13: Prov. Hainaut | C13: : | D13: C | E13: 1101 | G13: : | H13: C | I13: : | J13: C | K13: 1367 | M13: : | N13: C | O13: 1364 | Q13: 263 | S13: 443 | U13: 459 | W13: : | X13: bC | Y13: : | Z13: C | AA13: 470 | AC13: =Post2020_Derivation!G13 -> 322 | AD13: =IF(Post2020_Derivation!H13="","",Post2020_Derivation!H13) -> #NAME? | AE13: =Post2020_Derivation!M13 -> 310 | AF13: =IF(Post2020_Derivation!N13="","",Post2020_Derivation!N13) -> #NAME? | AG13: =Post2020_Derivation!S13 | AH13: =IF(Post2020_Derivation!T13="","",Post2020_Derivation!T13) -> #NAME?
A14: BE33 | B14: Prov. Liège | C14: : | D14: C | E14: 1140 | G14: : | H14: C | I14: : | J14: C | K14: 625 | M14: 667 | O14: 589 | Q14: 1094 | S14: 1086 | U14: 1167 | W14: 475 | X14: b | Y14: : | Z14: C | AA14: 571 | AC14: =Post2020_Derivation!G14 | AD14: =IF(Post2020_Derivation!H14="","",Post2020_Derivation!H14) -> #NAME? | AE14: =Post2020_Derivation!M14 -> 650 | AF14: =IF(Post2020_Derivation!N14="","",Post2020_Derivation!N14) -> #NAME? | AG14: =Post2020_Derivation!S14 -> 624 | AH14: =IF(Post2020_Derivation!T14="","",Post2020_Derivation!T14) -> #NAME?
A15: BE34 | B15: Prov. Luxembourg (BE) | C15: : | D15: C | E15: : | F15: C | G15: : | H15: C | I15: : | J15: C | K15: : | L15: C | M15: : | N15: C | O15: : | P15: C | Q15: 233 | S15: : | T15: C | U15: 237 | W15: : | X15: bC | Y15: 248 | AA15: : | AB15: C | AC15: =Post2020_Derivation!G15 -> 232 | AD15: =IF(Post2020_Derivation!H15="","",Post2020_Derivation!H15) -> #NAME? | AE15: =Post2020_Derivation!M15 -> 231 | AF15: =IF(Post2020_Derivation!N15="","",Post2020_Derivation!N15) -> #NAME? | AG15: =Post2020_Derivation!S15 | AH15: =IF(Post2020_Derivation!T15="","",Post2020_Derivation!T15) -> #NAME?
A16: BE35 | B16: Prov. Namur | C16: 466 | E16: : | F16: C | G16: 75 | I16: 59 | K16: : | L16: C | M16: 36 | O16: : | P16: C | Q16: 54 | S16: : | T16: C | U16: 61 | W16: 37 | X16: b | Y16: 45 | AA16: : | AB16: C | AC16: =Post2020_Derivation!G16 -> 60 | AD16: =IF(Post2020_Derivation!H16="","",Post2020_Derivation!H16) -> #NAME? | AE16: =Post2020_Derivation!M16 -> 72 | AF16: =IF(Post2020_Derivation!N16="","",Post2020_Derivation!N16) -> #NAME? | AG16: =Post2020_Derivation!S16 | AH16: =IF(Post2020_Derivation!T16="","",Post2020_Derivation!T16) -> #NAME?
A17: BG | B17: Bulgaria | C17: 10479 | E17: 10570 | G17: 10164 | I17: 12813 | K17: 12789 | M17: 12800 | O17: 17665 | Q17: 21021 | S17: 22051 | U17: 24488 | W17: 23946 | X17: b | Y17: 22566 | AA17: 25345 | AC17: =Post2020_Derivation!G19 -> 26364 | AD17: =IF(Post2020_Derivation!H19="","",Post2020_Derivation!H19) -> #NAME? | AE17: =Post2020_Derivation!M19 -> 25265 | AF17: =IF(Post2020_Derivation!N19="","",Post2020_Derivation!N19) -> #NAME? | AG17: =Post2020_Derivation!S19 -> 25440 | AH17: =IF(Post2020_Derivation!T19="","",Post2020_Derivation!T19) -> #NAME?
A18: BG3 | B18: Severna i Yugoiztochna Bulgaria | C18: 6485 | E18: 7088 | G18: 7725 | I18: 8840 | K18: 8389 | M18: 8985 | O18: 12540 | Q18: 15140 | S18: 15905 | U18: 16577 | W18: 15124 | X18: b | Y18: 12728 | AA18: 12787 | AC18: =Post2020_Derivation!G20 -> 12482 | AD18: =IF(Post2020_Derivation!H20="","",Post2020_Derivation!H20) -> #NAME? | AE18: =Post2020_Derivation!M20 -> 12665 | AF18: =IF(Post2020_Derivation!N20="","",Post2020_Derivation!N20) -> #NAME? | AG18: =Post2020_Derivation!S20 -> 12792 | AH18: =IF(Post2020_Derivation!T20="","",Post2020_Derivation!T20) -> #NAME?
A19: BG31 | B19: Severozapaden | C19: 109 | E19: 53 | G19: 28 | I19: 35 | K19: 56 | M19: 94 | O19: 299 | Q19: 336 | S19: : | T19: C | U19: : | V19: C | W19: : | X19: bC | Y19: 2216 | AA19: 2810 | AC19: =Post2020_Derivation!G21 -> 3723 | AD19: =IF(Post2020_Derivation!H21="","",Post2020_Derivation!H21) -> #NAME? | AE19: =Post2020_Derivation!M21 -> 4148 | AF19: =IF(Post2020_Derivation!N21="","",Post2020_Derivation!N21) -> #NAME? | AG19: =Post2020_Derivation!S21 -> 4432 | AH19: =IF(Post2020_Derivation!T21="","",Post2020_Derivation!T21) -> #NAME?
A20: BG32 | B20: Severen tsentralen | C20: 534 | E20: 541 | G20: 639 | I20: 933 | K20: 1140 | M20: 1026 | O20: 1196 | Q20: 1608 | S20: 1888 | U20: 1997 | W20: 2069 | X20: b | Y20: 2176 | AA20: 2154 | AC20: =Post2020_Derivation!G22 -> 2354 | AD20: =IF(Post2020_Derivation!H22="","",Post2020_Derivation!H22) -> #NAME? | AE20: =Post2020_Derivation!M22 -> 2424 | AF20: =IF(Post2020_Derivation!N22="","",Post2020_Derivation!N22) -> #NAME? | AG20: =Post2020_Derivation!S22 -> 2784 | AH20: =IF(Post2020_Derivation!T22="","",Post2020_Derivation!T22) -> #NAME?
A21: BG33 | B21: Severoiztochen | C21: 316 | E21: 409 | G21: 366 | I21: 1216 | K21: 1146 | M21: 1055 | O21: 1199 | Q21: 1255 | S21: : | T21: C | U21: : | V21: C | W21: : | X21: bC | Y21: 258 | AA21: 59 | AC21: =Post2020_Derivation!G23 -> 56 | AD21: =IF(Post2020_Derivation!H23="","",Post2020_Derivation!H23) -> #NAME? | AE21: =Post2020_Derivation!M23 -> 98 | AF21: =IF(Post2020_Derivation!N23="","",Post2020_Derivation!N23) -> #NAME? | AG21: =Post2020_Derivation!S23 -> 65 | AH21: =IF(Post2020_Derivation!T23="","",Post2020_Derivation!T23) -> #NAME?
A22: BG34 | B22: Yugoiztochen | C22: 5526 | E22: 6085 | G22: 6692 | I22: 6656 | K22: 6047 | M22: 6810 | O22: 9846 | Q22: 11941 | S22: 12492 | U22: 11451 | W22: 10197 | X22: b | Y22: 8078 | AA22: 7764 | AC22: =Post2020_Derivation!G24 -> 6344 | AD22: =IF(Post2020_Derivation!H24="","",Post2020_Derivation!H24) -> #NAME? | AE22: =Post2020_Derivation!M24 -> 5970 | AF22: =IF(Post2020_Derivation!N24="","",Post2020_Derivation!N24) -> #NAME? | AG22: =Post2020_Derivation!S24 -> 5539 | AH22: =IF(Post2020_Derivation!T24="","",Post2020_Derivation!T24) -> #NAME?
A23: BG4 | B23: Yugozapadna i Yuzhna tsentralna Bulgaria | C23: 3994 | E23: 3482 | G23: 2439 | I23: 3973 | K23: 4400 | M23: 3815 | O23: 5125 | Q23: 5881 | S23: 6146 | U23: 7911 | W23: 8822 | X23: b | Y23: 9838 | AA23: 12558 | AC23: =Post2020_Derivation!G25 -> 13937 | AD23: =IF(Post2020_Derivation!H25="","",Post2020_Derivation!H25) -> #NAME? | AE23: =Post2020_Derivation!M25 -> 12670 | AF23: =IF(Post2020_Derivation!N25="","",Post2020_Derivation!N25) -> #NAME? | AG23: =Post2020_Derivation!S25 -> 12705 | AH23: =IF(Post2020_Derivation!T25="","",Post2020_Derivation!T25) -> #NAME?
A24: BG41 | B24: Yugozapaden | C24: 3800 | E24: 3125 | G24: 2004 | I24: 3424 | K24: 3663 | M24: 2992 | O24: 3863 | Q24: 4267 | S24: 4526 | U24: 4854 | W24: 4037 | X24: b | Y24: 3189 | AA24: 5410 | AC24: =Post2020_Derivation!G26 -> 6336 | AD24: =IF(Post2020_Derivation!H26="","",Post2020_Derivation!H26) -> #NAME? | AE24: =Post2020_Derivation!M26 -> 6171 | AF24: =IF(Post2020_Derivation!N26="","",Post2020_Derivation!N26) -> #NAME? | AG24: =Post2020_Derivation!S26 -> 6160 | AH24: =IF(Post2020_Derivation!T26="","",Post2020_Derivation!T26) -> #NAME?
A25: BG42 | B25: Yuzhen tsentralen | C25: 194 | E25: 357 | G25: 435 | I25: 549 | K25: 737 | M25: 823 | O25: 1262 | Q25: 1614 | S25: 1620 | U25: 3057 | W25: 4785 | X25: b | Y25: 6649 | AA25: 7148 | AC25: =Post2020_Derivation!G27 -> 7585 | AD25: =IF(Post2020_Derivation!H27="","",Post2020_Derivation!H27) -> #NAME? | AE25: =Post2020_Derivation!M27 -> 6475 | AF25: =IF(Post2020_Derivation!N27="","",Post2020_Derivation!N27) -> #NAME? | AG25: =Post2020_Derivation!S27 -> 6510 | AH25: =IF(Post2020_Derivation!T27="","",Post2020_Derivation!T27) -> #NAME?
A26: CZ | B26: Czechia | C26: 159267 | D26: p | E26: 137732 | G26: 139129 | I26: 147552 | K26: 143227 | M26: 142556 | O26: 148509 | Q26: 159126 | S26: 168427 | U26: 177127 | W26: 181486 | Y26: 181861 | AA26: 175470 | AC26: =Post2020_Derivation!G28 -> 174384 | AD26: =IF(Post2020_Derivation!H28="","",Post2020_Derivation!H28) -> #NAME? | AE26: =Post2020_Derivation!M28 -> 172000 | AF26: =IF(Post2020_Derivation!N28="","",Post2020_Derivation!N28) -> #NAME? | AG26: =Post2020_Derivation!S28 -> 172720 | AH26: =IF(Post2020_Derivation!T28="","",Post2020_Derivation!T28) -> #NAME?
A27: CZ0 | B27: Česko | C27: 159267 | D27: p | E27: 137732 | G27: 139129 | I27: 147552 | K27: 143227 | M27: 142556 | O27: 148509 | Q27: 159126 | S27: 168427 | U27: 177127 | W27: 181486 | Y27: 181861 | AA27: 175470 | AC27: =Post2020_Derivation!G29 -> 174384 | AD27: =IF(Post2020_Derivation!H29="","",Post2020_Derivation!H29) -> #NAME? | AE27: =Post2020_Derivation!M29 -> 172000 | AF27: =IF(Post2020_Derivation!N29="","",Post2020_Derivation!N29) -> #NAME? | AG27: =Post2020_Derivation!S29 -> 172720 | AH27: =IF(Post2020_Derivation!T29="","",Post2020_Derivation!T29) -> #NAME?
A28: CZ01 | B28: Praha | C28: 2874 | D28: p | E28: 2383 | G28: 1794 | I28: 1662 | K28: 1582 | M28: 1647 | O28: 909 | Q28: 2035 | S28: 1392 | U28: 2779 | W28: 2784 | Y28: 2397 | AA28: 2311 | AC28: =Post2020_Derivation!G30 -> 1908 | AD28: =IF(Post2020_Derivation!H30="","",Post2020_Derivation!H30) -> #NAME? | AE28: =Post2020_Derivation!M30 -> 3572 | AF28: =IF(Post2020_Derivation!N30="","",Post2020_Derivation!N30) -> #NAME? | AG28: =Post2020_Derivation!S30 -> 3008 | AH28: =IF(Post2020_Derivation!T30="","",Post2020_Derivation!T30) -> #NAME?
A29: CZ02 | B29: Střední Čechy | C29: 41774 | D29: p | E29: 38567 | G29: 38223 | I29: 42292 | K29: 40165 | M29: 39447 | O29: 41983 | Q29: 43888 | S29: 45706 | U29: 46151 | W29: 46906 | Y29: 47312 | AA29: 47537 | AC29: =Post2020_Derivation!G31 -> 48720 | AD29: =IF(Post2020_Derivation!H31="","",Post2020_Derivation!H31) -> #NAME? | AE29: =Post2020_Derivation!M31 -> 47040 | AF29: =IF(Post2020_Derivation!N31="","",Post2020_Derivation!N31) -> #NAME? | AG29: =Post2020_Derivation!S31 -> 47508 | AH29: =IF(Post2020_Derivation!T31="","",Post2020_Derivation!T31) -> #NAME?
A30: CZ03 | B30: Jihozápad | C30: 23685 | D30: p | E30: 18813 | G30: 17962 | I30: 18499 | K30: 20166 | M30: 20533 | O30: 22732 | Q30: 23450 | S30: 24722 | U30: 27064 | W30: 28012 | Y30: 27020 | AA30: 25436 | AC30: =Post2020_Derivation!G32 -> 26167 | AD30: =IF(Post2020_Derivation!H32="","",Post2020_Derivation!H32) -> #NAME? | AE30: =Post2020_Derivation!M32 -> 24500 | AF30: =IF(Post2020_Derivation!N32="","",Post2020_Derivation!N32) -> #NAME? | AG30: =Post2020_Derivation!S32 -> 24505 | AH30: =IF(Post2020_Derivation!T32="","",Post2020_Derivation!T32) -> #NAME?
A31: CZ04 | B31: Severozápad | C31: 11293 | D31: p | E31: 9938 | G31: 10097 | I31: 11648 | K31: 11559 | M31: 11833 | O31: 11750 | Q31: 13393 | S31: 14613 | U31: 14228 | W31: 14186 | Y31: 14141 | AA31: 13141 | AC31: =Post2020_Derivation!G33 -> 11716 | AD31: =IF(Post2020_Derivation!H33="","",Post2020_Derivation!H33) -> #NAME? | AE31: =Post2020_Derivation!M33 -> 11712 | AF31: =IF(Post2020_Derivation!N33="","",Post2020_Derivation!N33) -> #NAME? | AG31: =Post2020_Derivation!S33 -> 11858 | AH31: =IF(Post2020_Derivation!T33="","",Post2020_Derivation!T33) -> #NAME?
A32: CZ05 | B32: Severovýchod | C32: 33672 | D32: p | E32: 28917 | G32: 33085 | I32: 31723 | K32: 28783 | M32: 29973 | O32: 31772 | Q32: 34736 | S32: 37404 | U32: 41356 | W32: 42261 | Y32: 43915 | AA32: 41768 | AC32: =Post2020_Derivation!G34 -> 42419 | AD32: =IF(Post2020_Derivation!H34="","",Post2020_Derivation!H34) -> #NAME? | AE32: =Post2020_Derivation!M34 -> 41181 | AF32: =IF(Post2020_Derivation!N34="","",Post2020_Derivation!N34) -> #NAME? | AG32: =Post2020_Derivation!S34 -> 39976 | AH32: =IF(Post2020_Derivation!T34="","",Post2020_Derivation!T34) -> #NAME?
A33: CZ06 | B33: Jihovýchod | C33: 17439 | D33: p | E33: 14277 | G33: 13176 | I33: 14326 | K33: 13365 | M33: 13209 | O33: 13348 | Q33: 13479 | S33: 13337 | U33: 13455 | W33: 14254 | Y33: 14331 | AA33: 13835 | AC33: =Post2020_Derivation!G35 -> 14364 | AD33: =IF(Post2020_Derivation!H35="","",Post2020_Derivation!H35) -> #NAME? | AE33: =Post2020_Derivation!M35 -> 13632 | AF33: =IF(Post2020_Derivation!N35="","",Post2020_Derivation!N35) -> #NAME? | AG33: =Post2020_Derivation!S35 -> 13920 | AH33: =IF(Post2020_Derivation!T35="","",Post2020_Derivation!T35) -> #NAME?
A34: CZ07 | B34: Střední Morava | C34: 8920 | D34: p | E34: 6499 | G34: 6216 | I34: 7495 | K34: 7486 | M34: 7066 | O34: 6982 | Q34: 7564 | S34: 8209 | U34: 7947 | W34: 7599 | Y34: 7321 | AA34: 7075 | AC34: =Post2020_Derivation!G36 -> 6604 | AD34: =IF(Post2020_Derivation!H36="","",Post2020_Derivation!H36) -> #NAME? | AE34: =Post2020_Derivation!M36 -> 7192 | AF34: =IF(Post2020_Derivation!N36="","",Post2020_Derivation!N36) -> #NAME? | AG34: =Post2020_Derivation!S36 -> 7139 | AH34: =IF(Post2020_Derivation!T36="","",Post2020_Derivation!T36) -> #NAME?
A35: CZ08 | B35: Moravskoslezsko | C35: 19609 | D35: p | E35: 18339 | G35: 18575 | I35: 19906 | K35: 20122 | M35: 18848 | O35: 19033 | Q35: 20582 | S35: 23046 | U35: 24146 | W35: 25483 | Y35: 25424 | AA35: 24368 | AC35: =Post2020_Derivation!G37 -> 23324 | AD35: =IF(Post2020_Derivation!H37="","",Post2020_Derivation!H37) -> #NAME? | AE35: =Post2020_Derivation!M37 -> 23436 | AF35: =IF(Post2020_Derivation!N37="","",Post2020_Derivation!N37) -> #NAME? | AG35: =Post2020_Derivation!S37 -> 24250 | AH35: =IF(Post2020_Derivation!T37="","",Post2020_Derivation!T37) -> #NAME?
A36: CZZ | B36: Extra-Regio NUTS 1 | C36: 0 | D36: p | E36: 0 | G36: 0 | I36: 0 | K36: 0 | M36: : | O36: : | Q36: : | S36: : | U36: 0 | W36: 0 | Y36: : | AA36: : | AC36: =Post2020_Derivation!G38 | AD36: =IF(Post2020_Derivation!H38="","",Post2020_Derivation!H38) -> #NAME? | AE36: =Post2020_Derivation!M38 | AF36: =IF(Post2020_Derivation!N38="","",Post2020_Derivation!N38) -> #NAME? | AG36: =Post2020_Derivation!S38 | AH36: =IF(Post2020_Derivation!T38="","",Post2020_Derivation!T38) -> #NAME?
A37: CZZZ | B37: Extra-Regio NUTS 2 | C37: 0 | D37: p | E37: 0 | G37: 0 | I37: 0 | K37: 0 | M37: : | O37: : | Q37: : | S37: : | U37: 0 | W37: 0 | Y37: : | AA37: : | AC37: =Post2020_Derivation!G39 | AD37: =IF(Post2020_Derivation!H39="","",Post2020_Derivation!H39) -> #NAME? | AE37: =Post2020_Derivation!M39 | AF37: =IF(Post2020_Derivation!N39="","",Post2020_Derivation!N39) -> #NAME? | AG37: =Post2020_Derivation!S39 | AH37: =IF(Post2020_Derivation!T39="","",Post2020_Derivation!T39) -> #NAME?
A38: DK | B38: Denmark | C38: 6832 | E38: 4494 | G38: 4507 | I38: 5980 | K38: 5143 | M38: 4625 | O38: 4710 | Q38: 4843 | S38: 4005 | T38: b | U38: 4079 | W38: 4324 | Y38: 3818 | AA38: 3632 | AC38: =Post2020_Derivation!G40 -> 3749 | AD38: =IF(Post2020_Derivation!H40="","",Post2020_Derivation!H40) -> #NAME? | AE38: =Post2020_Derivation!M40 -> 3888 | AF38: =IF(Post2020_Derivation!N40="","",Post2020_Derivation!N40) -> #NAME? | AG38: =Post2020_Derivation!S40 -> 3950 | AH38: =IF(Post2020_Derivation!T40="","",Post2020_Derivation!T40) -> #NAME?
A39: DK0 | B39: Danmark | C39: 6832 | E39: 4494 | G39: 4507 | I39: 5980 | K39: 5143 | M39: 4625 | O39: 4710 | Q39: 4843 | S39: 4005 | T39: b | U39: 4079 | W39: 4324 | Y39: 3818 | AA39: 3632 | AC39: =Post2020_Derivation!G41 -> 3749 | AD39: =IF(Post2020_Derivation!H41="","",Post2020_Derivation!H41) -> #NAME? | AE39: =Post2020_Derivation!M41 -> 3888 | AF39: =IF(Post2020_Derivation!N41="","",Post2020_Derivation!N41) -> #NAME? | AG39: =Post2020_Derivation!S41 -> 3950 | AH39: =IF(Post2020_Derivation!T41="","",Post2020_Derivation!T41) -> #NAME?
A40: DK01 | B40: Hovedstaden | C40: 203 | E40: 120 | G40: 128 | I40: : | J40: C | K40: : | L40: C | M40: : | N40: C | O40: : | P40: C | Q40: : | R40: C | S40: 291 | T40: b | U40: : | V40: C | W40: : | X40: C | Y40: 361 | AA40: 295 | AC40: =Post2020_Derivation!G42 -> 288 | AD40: =IF(Post2020_Derivation!H42="","",Post2020_Derivation!H42) -> #NAME? | AE40: =Post2020_Derivation!M42 -> 242 | AF40: =IF(Post2020_Derivation!N42="","",Post2020_Derivation!N42) -> #NAME? | AG40: =Post2020_Derivation!S42 -> 220 | AH40: =IF(Post2020_Derivation!T42="","",Post2020_Derivation!T42) -> #NAME?
...

Sheet LocalUnits_Merged
A1: GEO code | B1: GEO label | C1: 2008 | D1: flag_2008 | E1: 2009 | F1: flag_2009 | G1: 2010 | H1: flag_2010 | I1: 2011 | J1: flag_2011 | K1: 2012 | L1: flag_2012 | M1: 2013 | N1: flag_2013 | O1: 2014 | P1: flag_2014 | Q1: 2015 | R1: flag_2015 | S1: 2016 | T1: flag_2016 | U1: 2017 | V1: flag_2017 | W1: 2018 | X1: flag_2018 | Y1: 2019 | Z1: flag_2019 | AA1: 2020 | AB1: flag_2020 | AC1: 2021 | AD1: flag_2021 | AE1: 2022 | AF1: flag_2022 | AG1: 2023 | AH1: flag_2023
A2: BE | B2: Belgium | C2: 583 | E2: 469 | G2: 553 | I2: 441 | K2: 383 | M2: 415 | O2: 382 | Q2: 369 | S2: 350 | U2: 393 | W2: 425 | X2: b | Y2: 461 | AA2: 510 | AC2: 336 | AE2: 543 | AG2: 487
A3: BE1 | B3: Région de Bruxelles-Capitale/Brussels Hoofdstedelijk Gewest | C3: : | D3: C | E3: 32 | G3: 30 | I3: 27 | K3: 21 | M3: 22 | O3: 18 | Q3: 18 | S3: 21 | U3: 22 | W3: 22 | X3: b | Y3: 30 | AA3: 30 | AC3: 17 | AE3: 28 | AG3: 25
A4: BE10 | B4: Région de Bruxelles-Capitale/Brussels Hoofdstedelijk Gewest | C4: : | D4: C | E4: 32 | G4: 30 | I4: 27 | K4: 21 | M4: 22 | O4: 18 | Q4: 18 | S4: 21 | U4: 22 | W4: 22 | X4: b | Y4: 30 | AA4: 30 | AC4: 17 | AE4: 28 | AG4: 25
A5: BE2 | B5: Vlaams Gewest | C5: : | D5: C | E5: 326 | G5: 380 | I5: 308 | K5: 274 | M5: 294 | O5: 270 | Q5: 267 | S5: 247 | U5: 268 | W5: 309 | X5: b | Y5: 331 | AA5: 370 | AC5: : | AD5: C | AE5: 395 | AG5: 350
A6: BE21 | B6: Prov. Antwerpen | C6: 114 | E6: : | F6: C | G6: 88 | I6: 78 | K6: 66 | M6: 74 | O6: 76 | Q6: 68 | S6: 63 | U6: 71 | W6: 68 | X6: b | Y6: 78 | AA6: 86 | AC6: 56 | AE6: 95 | AG6: 78
A7: BE22 | B7: Prov. Limburg (BE) | C7: : | D7: C | E7: : | F7: C | G7: : | H7: C | I7: 52 | K7: 50 | M7: 52 | O7: 45 | Q7: 41 | S7: 42 | U7: 41 | W7: 52 | X7: b | Y7: 56 | AA7: 54 | AC7: : | AD7: C | AE7: 70 | AG7: 66
A8: BE23 | B8: Prov. Oost-Vlaanderen | C8: : | D8: C | E8: 78 | G8: 89 | I8: 68 | K8: 61 | M8: 72 | O8: 58 | Q8: 71 | S8: 61 | U8: 73 | W8: 80 | X8: b | Y8: 89 | AA8: 91 | AC8: 56 | AE8: 88 | AG8: 78
A9: BE24 | B9: Prov. Vlaams-Brabant | C9: : | D9: C | E9: 31 | G9: : | H9: C | I9: 32 | K9: 25 | M9: 33 | O9: 28 | Q9: 30 | S9: 25 | U9: 27 | W9: 35 | X9: b | Y9: 31 | AA9: 48 | AC9: 21 | AE9: 38 | AG9: 36
A10: BE25 | B10: Prov. West-Vlaanderen | C10: 89 | E10: 71 | G10: 95 | I10: 78 | K10: 72 | M10: 63 | O10: 63 | Q10: 57 | S10: 56 | U10: 56 | W10: 74 | X10: b | Y10: 77 | AA10: 91 | AC10: 69 | AE10: 104 | AG10: 92
A11: BE3 | B11: Région wallonne | C11: : | D11: C | E11: 109 | G11: 139 | I11: 102 | K11: 87 | M11: 91 | O11: 87 | Q11: 79 | S11: 76 | U11: 94 | W11: 83 | X11: b | Y11: 90 | AA11: 104 | AC11: : | AD11: C | AE11: 114 | AG11: 104
A12: BE31 | B12: Prov. Brabant wallon | C12: : | D12: C | E12: 5 | G12: : | H12: C | I12: 10 | K12: 12 | M12: 10 | O12: 5 | Q12: 4 | S12: 9 | U12: 9 | W12: : | X12: bC | Y12: : | Z12: C | AA12: 13 | AC12: 3 | AE12: 12 | AG12: 7
A13: BE32 | B13: Prov. Hainaut | C13: : | D13: C | E13: 33 | G13: : | H13: C | I13: : | J13: C | K13: 24 | M13: : | N13: C | O13: 24 | Q13: 23 | S13: 20 | U13: 21 | W13: : | X13: bC | Y13: : | Z13: C | AA13: 35 | AC13: 23 | AE13: 31 | AG13: : | AH13: C
A14: BE33 | B14: Prov. Liège | C14: : | D14: C | E14: 45 | G14: : | H14: C | I14: : | J14: C | K14: 44 | M14: 47 | O14: 45 | Q14: 41 | S14: 36 | U14: 47 | W14: 38 | X14: b | Y14: : | Z14: C | AA14: 41 | AC14: : | AD14: C | AE14: 50 | AG14: 48
A15: BE34 | B15: Prov. Luxembourg (BE) | C15: : | D15: C | E15: : | F15: C | G15: : | H15: C | I15: : | J15: C | K15: : | L15: C | M15: : | N15: C | O15: : | P15: C | Q15: 3 | S15: : | T15: C | U15: 5 | W15: : | X15: bC | Y15: 4 | AA15: : | AB15: C | AC15: 4 | AE15: 3 | AG15: : | AH15: C
A16: BE35 | B16: Prov. Namur | C16: 20 | E16: : | F16: C | G16: 18 | I16: 12 | K16: : | L16: C | M16: 7 | O16: : | P16: C | Q16: 8 | S16: : | T16: C | U16: 12 | W16: 7 | X16: b | Y16: 7 | AA16: : | AB16: C | AC16: 10 | AE16: 18 | AG16: : | AH16: C
A17: BG | B17: Bulgaria | C17: 99 | E17: 104 | G17: 110 | I17: 113 | K17: 113 | M17: 114 | O17: 117 | Q17: 118 | S17: 123 | U17: 120 | W17: 129 | X17: b | Y17: 145 | AA17: 148 | AC17: 156 | AE17: 155 | AG17: 159
A18: BG3 | B18: Severna i Yugoiztochna Bulgaria | C18: 53 | E18: 57 | G18: 62 | I18: 64 | K18: 64 | M18: 63 | O18: 63 | Q18: 66 | S18: 66 | U18: 64 | W18: 62 | X18: b | Y18: 69 | AA18: 76 | AC18: 79 | AE18: 85 | AG18: 82
A19: BG31 | B19: Severozapaden | C19: 8 | E19: 7 | G19: 4 | I19: 7 | K19: 6 | M19: 9 | O19: 11 | Q19: 10 | S19: 11 | U19: 11 | W19: 11 | X19: b | Y19: 13 | AA19: 17 | AC19: 17 | AE19: 17 | AG19: 16
A20: BG32 | B20: Severen tsentralen | C20: 14 | E20: 14 | G20: 18 | I20: 18 | K20: 21 | M20: 16 | O20: 14 | Q20: 15 | S20: 15 | U20: 16 | W20: 13 | X20: b | Y20: 15 | AA20: 18 | AC20: 22 | AE20: 24 | AG20: 24
A21: BG33 | B21: Severoiztochen | C21: 15 | E21: 20 | G21: 23 | I21: 21 | K21: 20 | M21: 20 | O21: 17 | Q21: 20 | S21: 20 | U21: 17 | W21: 18 | X21: b | Y21: 19 | AA21: 15 | AC21: 14 | AE21: 14 | AG21: 13
A22: BG34 | B22: Yugoiztochen | C22: 16 | E22: 16 | G22: 17 | I22: 18 | K22: 17 | M22: 18 | O22: 21 | Q22: 21 | S22: 20 | U22: 20 | W22: 20 | X22: b | Y22: 22 | AA22: 26 | AC22: 26 | AE22: 30 | AG22: 29
A23: BG4 | B23: Yugozapadna i Yuzhna tsentralna Bulgaria | C23: 46 | E23: 47 | G23: 48 | I23: 49 | K23: 49 | M23: 51 | O23: 54 | Q23: 52 | S23: 57 | U23: 56 | W23: 67 | X23: b | Y23: 76 | AA23: 72 | AC23: 77 | AE23: 70 | AG23: 77
A24: BG41 | B24: Yugozapaden | C24: 29 | E24: 27 | G24: 27 | I24: 30 | K24: 28 | M24: 31 | O24: 29 | Q24: 30 | S24: 32 | U24: 25 | W24: 32 | X24: b | Y24: 35 | AA24: 29 | AC24: 36 | AE24: 33 | AG24: 35
A25: BG42 | B25: Yuzhen tsentralen | C25: 17 | E25: 20 | G25: 21 | I25: 19 | K25: 21 | M25: 20 | O25: 25 | Q25: 22 | S25: 25 | U25: 31 | W25: 35 | X25: b | Y25: 41 | AA25: 43 | AC25: 41 | AE25: 37 | AG25: 42
A26: CZ | B26: Czechia | C26: 1323 | D26: p | E26: 1366 | G26: 1438 | I26: 1393 | K26: 1360 | M26: 1286 | O26: 1279 | Q26: 1273 | S26: 1292 | U26: 1281 | W26: 1301 | Y26: 1359 | AA26: 1360 | AC26: 1384 | AE26: 1376 | AG26: 1360
A27: CZ0 | B27: Česko | C27: 1323 | D27: p | E27: 1366 | G27: 1438 | I27: 1393 | K27: 1360 | M27: 1286 | O27: 1279 | Q27: 1273 | S27: 1292 | U27: 1281 | W27: 1301 | Y27: 1359 | AA27: 1360 | AC27: 1384 | AE27: 1376 | AG27: 1360
A28: CZ01 | B28: Praha | C28: 170 | D28: p | E28: 186 | G28: 209 | I28: 208 | K28: 198 | M28: 180 | O28: 175 | Q28: 181 | S28: 184 | U28: 156 | W28: 160 | Y28: 157 | AA28: 159 | AC28: 159 | AE28: 188 | AG28: 188
A29: CZ02 | B29: Střední Čechy | C29: 179 | D29: p | E29: 187 | G29: 234 | I29: 223 | K29: 220 | M29: 211 | O29: 226 | Q29: 216 | S29: 221 | U29: 213 | W29: 213 | Y29: 231 | AA29: 236 | AC29: 232 | AE29: 224 | AG29: 222
A30: CZ03 | B30: Jihozápad | C30: 153 | D30: p | E30: 162 | G30: 150 | I30: 151 | K30: 155 | M30: 141 | O30: 144 | Q30: 144 | S30: 157 | U30: 164 | W30: 172 | Y30: 173 | AA30: 169 | AC30: 191 | AE30: 175 | AG30: 169
A31: CZ04 | B31: Severozápad | C31: 140 | D31: p | E31: 138 | G31: 128 | I31: 122 | K31: 122 | M31: 109 | O31: 113 | Q31: 109 | S31: 110 | U31: 106 | W31: 108 | Y31: 112 | AA31: 102 | AC31: 116 | AE31: 96 | AG31: 98
A32: CZ05 | B32: Severovýchod | C32: 233 | D32: p | E32: 234 | G32: 257 | I32: 261 | K32: 252 | M32: 235 | O32: 233 | Q32: 234 | S32: 234 | U32: 241 | W32: 241 | Y32: 267 | AA32: 272 | AC32: 251 | AE32: 259 | AG32: 263
A33: CZ06 | B33: Jihovýchod | C33: 174 | D33: p | E33: 184 | G33: 181 | I33: 168 | K33: 163 | M33: 156 | O33: 159 | Q33: 163 | S33: 159 | U33: 169 | W33: 171 | Y33: 177 | AA33: 175 | AC33: 189 | AE33: 192 | AG33: 174
A34: CZ07 | B34: Střední Morava | C34: 143 | D34: p | E34: 150 | G34: 147 | I34: 137 | K34: 136 | M34: 133 | O34: 126 | Q34: 121 | S34: 119 | U34: 118 | W34: 123 | Y34: 122 | AA34: 120 | AC34: 127 | AE34: 116 | AG34: 121
A35: CZ08 | B35: Moravskoslezsko | C35: 131 | D35: p | E35: 125 | G35: 132 | I35: 123 | K35: 114 | M35: 121 | O35: 103 | Q35: 105 | S35: 108 | U35: 114 | W35: 113 | Y35: 120 | AA35: 127 | AC35: 119 | AE35: 126 | AG35: 125
A36: CZZ | B36: Extra-Regio NUTS 1 | C36: 0 | D36: p | E36: 0 | G36: 0 | I36: 0 | K36: 0 | M36: : | O36: : | Q36: : | S36: : | U36: 0 | W36: 0 | Y36: : | AA36: : | AC36: 0 | AE36: 0 | AG36: 0
A37: CZZZ | B37: Extra-Regio NUTS 2 | C37: 0 | D37: p | E37: 0 | G37: 0 | I37: 0 | K37: 0 | M37: : | O37: : | Q37: : | S37: : | U37: 0 | W37: 0 | Y37: : | AA37: : | AC37: 0 | AE37: 0 | AG37: 0
A38: DK | B38: Denmark | C38: 196 | E38: 200 | G38: 195 | I38: 196 | K38: 196 | M38: 174 | O38: 174 | Q38: 171 | S38: 171 | U38: 173 | W38: 167 | Y38: 170 | AA38: 163 | AC38: 163 | AE38: 162 | AG38: 158
A39: DK0 | B39: Danmark | C39: 196 | E39: 200 | G39: 195 | I39: 196 | K39: 196 | M39: 174 | O39: 174 | Q39: 171 | S39: 171 | U39: 173 | W39: 167 | Y39: 170 | AA39: 163 | AC39: 163 | AE39: 162 | AG39: 158
A40: DK01 | B40: Hovedstaden | C40: 28 | E40: 25 | G40: 25 | I40: 30 | K40: 28 | M40: 26 | O40: 26 | Q40: 26 | S40: 27 | U40: 25 | W40: 28 | Y40: 27 | AA40: 25 | AC40: 24 | AE40: 22 | AG40: 20
...

Sheet Wages_Merged
A1: GEO code | B1: GEO label | C1: 2008 | D1: flag_2008 | E1: 2009 | F1: flag_2009 | G1: 2010 | H1: flag_2010 | I1: 2011 | J1: flag_2011 | K1: 2012 | L1: flag_2012 | M1: 2013 | N1: flag_2013 | O1: 2014 | P1: flag_2014 | Q1: 2015 | R1: flag_2015 | S1: 2016 | T1: flag_2016 | U1: 2017 | V1: flag_2017 | W1: 2018 | X1: flag_2018 | Y1: 2019 | Z1: flag_2019 | AA1: 2020 | AB1: flag_2020 | AC1: 2021 | AD1: flag_2021 | AE1: 2022 | AF1: flag_2022 | AG1: 2023 | AH1: flag_2023
A2: BE | B2: Belgium | C2: 1538.9 | E2: 1343.1 | G2: 1313.6 | I2: 1430 | K2: 1453 | M2: 1511 | O2: 1632.1 | Q2: 1267.8 | S2: 1232.2 | U2: 1299.7 | W2: 1388.7 | X2: b | Y2: 1418 | AA2: 1337.4 | AC2: 1341.38 | AE2: 1467.63 | AG2: 1592.89
A3: BE1 | B3: Région de Bruxelles-Capitale/Brussels Hoofdstedelijk Gewest | C3: : | D3: C | E3: 197.1 | G3: 169.7 | I3: 183.6 | K3: 203.2 | M3: 213.5 | O3: 190.1 | Q3: 190.5 | S3: 193.6 | U3: 213.7 | W3: 171.2 | X3: b | Y3: 188.7 | AA3: 190.4 | AC3: 194.55 | AE3: 225.84 | AG3: 226.73
A4: BE10 | B4: Région de Bruxelles-Capitale/Brussels Hoofdstedelijk Gewest | C4: : | D4: C | E4: 197.1 | G4: 169.7 | I4: 183.6 | K4: 203.2 | M4: 213.5 | O4: 190.1 | Q4: 190.5 | S4: 193.6 | U4: 213.7 | W4: 171.2 | X4: b | Y4: 188.7 | AA4: 190.4 | AC4: 194.55 | AE4: 225.84 | AG4: 226.73
A5: BE2 | B5: Vlaams Gewest | C5: : | D5: C | E5: 1053.5 | G5: 1048 | I5: 1146.3 | K5: 1167 | M5: 1207.8 | O5: 1353.1 | Q5: 1007.4 | S5: 963.7 | U5: 1002.8 | W5: 1136.9 | X5: b | Y5: 1146.6 | AA5: 1088.1 | AC5: : | AD5: C | AE5: 1184.2 | AG5: 1309.13
A6: BE21 | B6: Prov. Antwerpen | C6: 433.9 | E6: : | F6: C | G6: 285.3 | I6: 309 | K6: 334.8 | M6: 352.4 | O6: 311.8 | Q6: 283.3 | S6: 247.2 | U6: 250.9 | W6: 279.4 | X6: b | Y6: 297.4 | AA6: 241.8 | AC6: 238.41 | AE6: 278.81 | AG6: 300.56
A7: BE22 | B7: Prov. Limburg (BE) | C7: : | D7: C | E7: : | F7: C | G7: : | H7: C | I7: 281.9 | K7: 282.9 | M7: 303.3 | O7: 475.3 | Q7: 171.5 | S7: 159.7 | U7: 179.4 | W7: 181.6 | X7: b | Y7: 178.7 | AA7: 165.7 | AC7: : | AD7: C | AE7: 148.8 | AG7: 181.38
A8: BE23 | B8: Prov. Oost-Vlaanderen | C8: : | D8: C | E8: 272.6 | G8: 360.1 | I8: 405.2 | K8: 424.5 | M8: 429.1 | O8: 439.8 | Q8: 438.8 | S8: 443.7 | U8: 464.3 | W8: 533 | X8: b | Y8: 539.4 | AA8: 539.7 | AC8: 551.97 | AE8: 602.88 | AG8: 696.97
A9: BE24 | B9: Prov. Vlaams-Brabant | C9: : | D9: C | E9: 82.2 | G9: : | H9: C | I9: 67.5 | K9: 66.2 | M9: 66.1 | O9: 73.4 | Q9: 57.7 | S9: 62.3 | U9: 53.6 | W9: 56.5 | X9: b | Y9: 46.2 | AA9: 58.2 | AC9: 63.81 | AE9: 56.83 | AG9: 41.83
A10: BE25 | B10: Prov. West-Vlaanderen | C10: 71.9 | E10: 64.7 | G10: 56.4 | I10: 82.7 | K10: 58.6 | M10: 56.9 | O10: 52.9 | Q10: 56.1 | S10: 50.8 | U10: 54.6 | W10: 86.4 | X10: b | Y10: 84.9 | AA10: 82.7 | AC10: 94.64 | AE10: 96.87 | AG10: 88.39
A11: BE3 | B11: Région wallonne | C11: : | D11: C | E11: 92.1 | G11: 95.5 | I11: 100 | K11: 82.7 | M11: 89.3 | O11: 86.9 | Q11: 69.1 | S11: 74.6 | U11: 81.4 | W11: 77.7 | X11: b | Y11: 81.7 | AA11: 58.7 | AC11: : | AD11: C | AE11: 57.24 | AG11: 56.2
A12: BE31 | B12: Prov. Brabant wallon | C12: : | D12: C | E12: 0.4 | G12: : | H12: C | I12: 3.5 | K12: 4.4 | M12: 4.8 | O12: 4.2 | Q12: 3.2 | S12: 3 | U12: 4.2 | W12: : | X12: bC | Y12: : | Z12: C | AA12: 5.8 | AC12: 3.81 | AE12: 4.41 | AG12: 4.81
A13: BE32 | B13: Prov. Hainaut | C13: : | D13: C | E13: 30.7 | G13: : | H13: C | I13: : | J13: C | K13: 46.1 | M13: : | N13: C | O13: 51.8 | Q13: 7.3 | S13: 16.3 | U13: 18.3 | W13: : | X13: bC | Y13: : | Z13: C | AA13: 20.7 | AC13: 11.84 | AE13: 14.01 | AG13: : | AH13: C
A14: BE33 | B14: Prov. Liège | C14: : | D14: C | E14: 37.4 | G14: : | H14: C | I14: : | J14: C | K14: 18.8 | M14: 20.4 | O14: 18.6 | Q14: 45.5 | S14: 43.5 | U14: 45.9 | W14: 15.5 | X14: b | Y14: : | Z14: C | AA14: 18.4 | AC14: : | AD14: C | AE14: 24.61 | AG14: 28.51
A15: BE34 | B15: Prov. Luxembourg (BE) | C15: : | D15: C | E15: : | F15: C | G15: : | H15: C | I15: : | J15: C | K15: : | L15: C | M15: : | N15: C | O15: : | P15: C | Q15: 11.7 | S15: : | T15: C | U15: 11.9 | W15: : | X15: bC | Y15: 12.4 | AA15: : | AB15: C | AC15: 11 | AE15: 11.46 | AG15: : | AH15: C
A16: BE35 | B16: Prov. Namur | C16: 9.9 | E16: : | F16: C | G16: 1.5 | I16: 1.3 | K16: : | L16: C | M16: 0.9 | O16: : | P16: C | Q16: 1.4 | S16: : | T16: C | U16: 1.2 | W16: 1.1 | X16: b | Y16: 1.3 | AA16: : | AB16: C | AC16: 2.17 | AE16: 2.76 | AG16: : | AH16: C
A17: BG | B17: Bulgaria | C17: 32.9 | E17: 37.3 | G17: 41.7 | I17: 51.9 | K17: 54.8 | M17: 54.3 | O17: 78.3 | Q17: 101.4 | S17: 115 | U17: 135.8 | W17: 151.2 | X17: b | Y17: 163.3 | AA17: 198.7 | AC17: 230.86 | AE17: 249.56 | AG17: 288.85
A18: BG3 | B18: Severna i Yugoiztochna Bulgaria | C18: 18.3 | E18: 22.8 | G18: 26.4 | I18: 32.1 | K18: 31.5 | M18: 33.8 | O18: 50.7 | Q18: 69.3 | S18: 76.9 | U18: 88.8 | W18: 90 | X18: b | Y18: 83 | AA18: 92 | AC18: 98.78 | AE18: 115.09 | AG18: 137.19
A19: BG31 | B19: Severozapaden | C19: 0.2 | E19: 0.1 | G19: 0 | I19: 0.1 | K19: 0.1 | M19: 0.2 | O19: : | P19: C | Q19: 2.6 | S19: 1.8 | U19: : | V19: C | W19: : | X19: bC | Y19: 14.2 | AA19: 20.5 | AC19: 29.49 | AE19: 36.51 | AG19: 42.06
