Workbook

Sheet Summary
A6: Enterprises by NUTS 2 region and NACE Rev.2 activity [sbs_r_nuts2021__custom_21203869]
A7: Open product page | B7: Open in Data Browser
A8: Description: | B8: -
A10: Last update of data: | D10: 09/02/2026 23:00
A11: Last change of data structure: | D11: 01/09/2025 23:00
B13: Institutional source(s)
C14: Eurostat
B15: Contents | C15: Time frequency [FREQ] | D15: Statistical classification of economic activities in the European Community (NACE Rev. 2) [NACE_R2] | E15: Economic indicator for structural business statistics [INDIC_SBS]
B16: Sheet 1 | C16: Annual [A] | D16: Manufacture of motor vehicles, trailers and semi-trailers [C29] | E16: Persons employed per local unit - number [EMP_PLOC_NR]
B17: Sheet 2 | C17: Annual [A] | D17: Manufacture of motor vehicles, trailers and semi-trailers [C29] | E17: Local units - number [LOC_NR]
B18: Sheet 3 | C18: Annual [A] | D18: Manufacture of motor vehicles, trailers and semi-trailers [C29] | E18: Wages and salaries in local units - million euro [WAGE_LOC_MEUR]

Sheet Sheet 1
A1: Data extracted on 28/04/2026 09:07:09 from [ESTAT]
A2: Dataset: | B2: Enterprises by NUTS 2 region and NACE Rev.2 activity [sbs_r_nuts2021__custom_21203869]
A3: Last updated: | B3: 09/02/2026 23:00
A5: Time frequency [FREQ] | C5: Annual [A]
A6: Statistical classification of economic activities in the European Community (NACE Rev. 2) [NACE_R2] | C6: Manufacture of motor vehicles, trailers and semi-trailers [C29]
A7: Economic indicator for structural business statistics [INDIC_SBS] | C7: Persons employed per local unit - number [EMP_PLOC_NR]
A9: TIME | B9: TIME | C9: 2021 | E9: 2022 | G9: 2023
A10: GEO (Codes) | B10: GEO (Labels)
A11: BE | B11: Belgium | C11: 87 | E11: 57 | G11: 61
A12: BE1 | B12: Région de Bruxelles-Capitale/Brussels Hoofdstedelijk Gewest | C12: 210 | E12: 144 | G12: 144
A13: BE10 | B13: Région de Bruxelles-Capitale/Brussels Hoofdstedelijk Gewest | C13: 210 | E13: 144 | G13: 144
A14: BE2 | B14: Vlaams Gewest | C14: : | D14: C | E14: 64 | G14: 70
A15: BE21 | B15: Prov. Antwerpen | C15: 110 | E15: 64 | G15: 76
A16: BE22 | B16: Prov. Limburg (BE) | C16: : | D16: C | E16: 43 | G16: 47
A17: BE23 | B17: Prov. Oost-Vlaanderen | C17: 206 | E17: 143 | G17: 160
A18: BE24 | B18: Prov. Vlaams-Brabant | C18: 60 | E18: 31 | G18: 24
A19: BE25 | B19: Prov. West-Vlaanderen | C19: 37 | E19: 24 | G19: 24
A20: BE3 | B20: Région wallonne | C20: : | D20: C | E20: 12 | G20: 12
A21: BE31 | B21: Prov. Brabant wallon | C21: 36 | E21: 11 | G21: 18
A22: BE32 | B22: Prov. Hainaut | C22: 14 | E22: 10 | G22: : | H22: C
A23: BE33 | B23: Prov. Liège | C23: : | D23: C | E23: 13 | G23: 13
A24: BE34 | B24: Prov. Luxembourg (BE) | C24: 58 | E24: 77 | G24: : | H24: C
A25: BE35 | B25: Prov. Namur | C25: 6 | E25: 4 | G25: : | H25: C
A26: BEZ | B26: Extra-Regio NUTS 1 | C26: : | D26: C | E26: 3 | G26: 4
A27: BEZZ | B27: Extra-Regio NUTS 2 | C27: : | D27: C | E27: 3 | G27: 4
A28: BG | B28: Bulgaria | C28: 169 | E28: 163 | G28: 160
A29: BG3 | B29: Severna i Yugoiztochna Bulgaria | C29: 158 | E29: 149 | G29: 156
A30: BG31 | B30: Severozapaden | C30: 219 | E30: 244 | G30: 277
A31: BG32 | B31: Severen tsentralen | C31: 107 | E31: 101 | G31: 116
A32: BG33 | B32: Severoiztochen | C32: 4 | E32: 7 | G32: 5
A33: BG34 | B33: Yugoiztochen | C33: 244 | E33: 199 | G33: 191
A34: BG4 | B34: Yugozapadna i Yuzhna tsentralna Bulgaria | C34: 181 | E34: 181 | G34: 165
A35: BG41 | B35: Yugozapaden | C35: 176 | E35: 187 | G35: 176
A36: BG42 | B36: Yuzhen tsentralen | C36: 185 | E36: 175 | G36: 155
A37: CZ | B37: Czechia | C37: 126 | E37: 125 | G37: 127
A38: CZ0 | B38: Česko | C38: 126 | E38: 125 | G38: 127
A39: CZ01 | B39: Praha | C39: 12 | E39: 19 | G39: 16
... A46: CZ08 | B46: Moravskoslezsko | C46: 196 | E46: 186 | G46: 194
A47: CZZ | B47: Extra-Regio NUTS 1 | C47: : | E47: : | G47: :
A48: CZZZ | B48: Extra-Regio NUTS 2 | C48: : | E48: : | G48: :
...

Sheet Sheet 2
A1: Data extracted on 28/04/2026 09:07:09 from [ESTAT]
A2: Dataset: | B2: Enterprises by NUTS 2 region and NACE Rev.2 activity [sbs_r_nuts2021__custom_21203869]
A3: Last updated: | B3: 09/02/2026 23:00
A5: Time frequency [FREQ] | C5: Annual [A]
A6: Statistical classification of economic activities in the European Community (NACE Rev. 2) [NACE_R2] | C6: Manufacture of motor vehicles, trailers and semi-trailers [C29]
A7: Economic indicator for structural business statistics [INDIC_SBS] | C7: Local units - number [LOC_NR]
A9: TIME | B9: TIME | C9: 2021 | E9: 2022 | G9: 2023
A10: GEO (Codes) | B10: GEO (Labels)
A11: BE | B11: Belgium | C11: 336 | E11: 543 | G11: 487
A12: BE1 | B12: Région de Bruxelles-Capitale/Brussels Hoofdstedelijk Gewest | C12: 17 | E12: 28 | G12: 25
A13: BE10 | B13: Région de Bruxelles-Capitale/Brussels Hoofdstedelijk Gewest | C13: 17 | E13: 28 | G13: 25
A14: BE2 | B14: Vlaams Gewest | C14: : | D14: C | E14: 395 | G14: 350
A15: BE21 | B15: Prov. Antwerpen | C15: 56 | E15: 95 | G15: 78
A16: BE22 | B16: Prov. Limburg (BE) | C16: : | D16: C | E16: 70 | G16: 66
A17: BE23 | B17: Prov. Oost-Vlaanderen | C17: 56 | E17: 88 | G17: 78
A18: BE24 | B18: Prov. Vlaams-Brabant | C18: 21 | E18: 38 | G18: 36
A19: BE25 | B19: Prov. West-Vlaanderen | C19: 69 | E19: 104 | G19: 92
A20: BE3 | B20: Région wallonne | C20: : | D20: C | E20: 114 | G20: 104
A21: BE31 | B21: Prov. Brabant wallon | C21: 3 | E21: 12 | G21: 7
A22: BE32 | B22: Prov. Hainaut | C22: 23 | E22: 31 | G22: : | H22: C
A23: BE33 | B23: Prov. Liège | C23: : | D23: C | E23: 50 | G23: 48
A24: BE34 | B24: Prov. Luxembourg (BE) | C24: 4 | E24: 3 | G24: : | H24: C
A25: BE35 | B25: Prov. Namur | C25: 10 | E25: 18 | G25: : | H25: C
A26: BEZ | B26: Extra-Regio NUTS 1 | C26: : | D26: C | E26: 6 | G26: 8
A27: BEZZ | B27: Extra-Regio NUTS 2 | C27: : | D27: C | E27: 6 | G27: 8
A28: BG | B28: Bulgaria | C28: 156 | E28: 155 | G28: 159
A29: BG3 | B29: Severna i Yugoiztochna Bulgaria | C29: 79 | E29: 85 | G29: 82
A30: BG31 | B30: Severozapaden | C30: 17 | E30: 17 | G30: 16
A31: BG32 | B31: Severen tsentralen | C31: 22 | E31: 24 | G31: 24
A32: BG33 | B32: Severoiztochen | C32: 14 | E32: 14 | G32: 13
A33: BG34 | B33: Yugoiztochen | C33: 26 | E33: 30 | G33: 29
A34: BG4 | B34: Yugozapadna i Yuzhna tsentralna Bulgaria | C34: 77 | E34: 70 | G34: 77
A35: BG41 | B35: Yugozapaden | C35: 36 | E35: 33 | G35: 35
A36: BG42 | B36: Yuzhen tsentralen | C36: 41 | E36: 37 | G36: 42
A37: CZ | B37: Czechia | C37: 1384 | E37: 1376 | G37: 1360
A38: CZ0 | B38: Česko | C38: 1384 | E38: 1376 | G38: 1360
A39: CZ01 | B39: Praha | C39: 159 | E39: 188 | G39: 188
... A57: DKZZ | B57: Extra-Regio NUTS 2 | C57: 0 | E57: 0 | G57: 0
A58: DE | B58: Germany | C58: 3695 | E58: 3720 | G58: 3717 | K58: ='Sheet 1'!G58*'Sheet 2'!G58 -> 847476
A59: DE1 | B59: Baden-Württemberg | C59: 700 | E59: 707 | G59: 696 | K59: ='Sheet 1'!G59*'Sheet 2'!G59 -> 228288
...

Sheet Sheet 3
A1: Data extracted on 28/04/2026 09:07:09 from [ESTAT]
A2: Dataset: | B2: Enterprises by NUTS 2 region and NACE Rev.2 activity [sbs_r_nuts2021__custom_21203869]
A3: Last updated: | B3: 09/02/2026 23:00
A5: Time frequency [FREQ] | C5: Annual [A]
A6: Statistical classification of economic activities in the European Community (NACE Rev. 2) [NACE_R2] | C6: Manufacture of motor vehicles, trailers and semi-trailers [C29]
A7: Economic indicator for structural business statistics [INDIC_SBS] | C7: Wages and salaries in local units - million euro [WAGE_LOC_MEUR]
A9: TIME | B9: TIME | C9: 2021 | E9: 2022 | G9: 2023
A10: GEO (Codes) | B10: GEO (Labels)
A11: BE | B11: Belgium | C11: 1341.38 | E11: 1467.63 | G11: 1592.89
A12: BE1 | B12: Région de Bruxelles-Capitale/Brussels Hoofdstedelijk Gewest | C12: 194.55 | E12: 225.84 | G12: 226.73
A13: BE10 | B13: Région de Bruxelles-Capitale/Brussels Hoofdstedelijk Gewest | C13: 194.55 | E13: 225.84 | G13: 226.73
A14: BE2 | B14: Vlaams Gewest | C14: : | D14: C | E14: 1184.2 | G14: 1309.13
A15: BE21 | B15: Prov. Antwerpen | C15: 238.41 | E15: 278.81 | G15: 300.56
A16: BE22 | B16: Prov. Limburg (BE) | C16: : | D16: C | E16: 148.8 | G16: 181.38
A17: BE23 | B17: Prov. Oost-Vlaanderen | C17: 551.97 | E17: 602.88 | G17: 696.97
A18: BE24 | B18: Prov. Vlaams-Brabant | C18: 63.81 | E18: 56.83 | G18: 41.83
A19: BE25 | B19: Prov. West-Vlaanderen | C19: 94.64 | E19: 96.87 | G19: 88.39
A20: BE3 | B20: Région wallonne | C20: : | D20: C | E20: 57.24 | G20: 56.2
A21: BE31 | B21: Prov. Brabant wallon | C21: 3.81 | E21: 4.41 | G21: 4.81
A22: BE32 | B22: Prov. Hainaut | C22: 11.84 | E22: 14.01 | G22: : | H22: C
A23: BE33 | B23: Prov. Liège | C23: : | D23: C | E23: 24.61 | G23: 28.51
A24: BE34 | B24: Prov. Luxembourg (BE) | C24: 11 | E24: 11.46 | G24: : | H24: C
A25: BE35 | B25: Prov. Namur | C25: 2.17 | E25: 2.76 | G25: : | H25: C
A26: BEZ | B26: Extra-Regio NUTS 1 | C26: : | D26: C | E26: 0.35 | G26: 0.84
A27: BEZZ | B27: Extra-Regio NUTS 2 | C27: : | D27: C | E27: 0.35 | G27: 0.84
A28: BG | B28: Bulgaria | C28: 230.86 | E28: 249.56 | G28: 288.85
A29: BG3 | B29: Severna i Yugoiztochna Bulgaria | C29: 98.78 | E29: 115.09 | G29: 137.19
A30: BG31 | B30: Severozapaden | C30: 29.49 | E30: 36.51 | G30: 42.06
A31: BG32 | B31: Severen tsentralen | C31: 24.14 | E31: 28.56 | G31: 41.43
A32: BG33 | B32: Severoiztochen | C32: 0.27 | E32: 0.48 | G32: 0.46
A33: BG34 | B33: Yugoiztochen | C33: 44.89 | E33: 49.53 | G33: 53.24
A34: BG4 | B34: Yugozapadna i Yuzhna tsentralna Bulgaria | C34: 132.08 | E34: 134.47 | G34: 151.66
A35: BG41 | B35: Yugozapaden | C35: 70.97 | E35: 76.96 | G35: 84.16
A36: BG42 | B36: Yuzhen tsentralen | C36: 61.11 | E36: 57.51 | G36: 67.5
A37: CZ | B37: Czechia | C37: 3379.89 | E37: 3815.9 | G37: 4323.06
A38: CZ0 | B38: Česko | C38: 3379.89 | E38: 3815.9 | G38: 4323.06
A39: CZ01 | B39: Praha | C39: 37.62 | E39: 58.78 | G39: 65.34
... A77: DE50 | B77: Bremen | C77: 956.27 | E77: 1075.47 | G77: 1103.17
A78: DE6 | B78: Hamburg | C78: : | D78: C | E78: : | F78: C | G78: : | H78: C
A79: DE60 | B79: Hamburg | C79: : | D79: C | E79: : | F79: C | G79: : | H79: C
...
